<?xml version="1.0" ?>
<!-- =================================================================================== -->
<!-- |    This document was autogenerated by xacro from 00-default.urdf.xacro          | -->
<!-- |    EDITING THIS FILE BY HAND IS NOT RECOMMENDED                                 | -->
<!-- =================================================================================== -->
<robot name="myfirst" xmlns:controller="http://playerstage.sourceforge.net/gazebo/xmlschema/#controller" xmlns:interface="http://playerstage.sourceforge.net/gazebo/xmlschema/#interface" xmlns:sensor="http://playerstage.sourceforge.net/gazebo/xmlschema/#sensor" xmlns:xacro="http://ros.org/wiki/xacro">
  <gazebo reference="camera_depth_frame">
    <sensor name="camera1" type="depth">
      <always_on>true</always_on>
      <update_rate>20.0</update_rate>
      <camera>
        <horizontal_fov>1.0471975512</horizontal_fov>
        <image>
          <format>R8G8B8</format>
          <width>640</width>
          <height>480</height>
        </image>
        <clip>
          <near>0.05</near>
          <far>8.0</far>
        </clip>
      </camera>
      <plugin filename="libgazebo_ros_openni_kinect.so" name="camera_depth_frame_kinect_controller">
        <baseline>0.1</baseline>
        <alwaysOn>true</alwaysOn>
        <updateRate>10</updateRate>
        <cameraName>camera1</cameraName>
        <imageTopicName>rgb/image_raw</imageTopicName>
        <cameraInfoTopicName>rgb/camera_info</cameraInfoTopicName>
        <depthImageTopicName>depth/image_raw</depthImageTopicName>
        <depthImageCameraInfoTopicName>depth/camera_info</depthImageCameraInfoTopicName>
        <pointCloudTopicName>depth/points</pointCloudTopicName>
        <frameName>camera_depth_optical_frame</frameName>
        <pointCloudCutoff>0.3</pointCloudCutoff>
        <distortion_k1>0.0</distortion_k1>
        <distortion_k2>0.0</distortion_k2>
        <distortion_k3>0.0</distortion_k3>
        <distortion_t1>0.0</distortion_t1>
        <distortion_t2>0.0</distortion_t2>
        <!--
          <CxPrime>0</CxPrime>
          <Cx>0</Cx>
          <Cy>0</Cy>
          <focalLength>0</focalLength>
          <hackBaseline>0</hackBaseline>
      -->
      </plugin>
    </sensor>
  </gazebo>
  <material name="blue">
    <color rgba="0 0 0.8 1"/>
  </material>
  <!--                          Frame                           -->
  <link name="base_link"/>
  <link name="chassis">
    <visual>
      <geometry>
        <box size="0.8128 0.7112 0.1524"/>
      </geometry>
      <origin xyz="0 0 0.0762"/>
      <material name="blue"/>
    </visual>
    <collision>
      <geometry>
        <box size="0.8128 0.7112 0.1524"/>
      </geometry>
      <origin xyz="0 0 0.0762"/>
    </collision>
    <inertial>
      <mass value="50"/>
      <inertia ixx="2.20429666667" ixy="0" ixz="0" iyy="2.84945666667" iyz="0" izz="2.84945666667"/>
      <origin xyz="0 0 0.0762"/>
    </inertial>
  </link>
  <joint name="base_link_to_chassis" type="fixed">
    <parent link="base_link"/>
    <child link="chassis"/>
    <axis xyz="0 0 0.0"/>
    <origin rpy="0 0 0"/>
  </joint>
  <!-- <xacro:six_wheel_diff_drive name="tank_drive" parent="base_link"
    z_offset="0.0" drop_wheel_height="0.003175"
    wheel_separation="0.6096" wheelbase_length="0.6096"
    wheel_radius="0.1016" wheel_width="0.0381" wheel_mass="1" /> -->
  <link name="fl_swerve_pivot">
    <visual>
      <geometry>
        <cylinder length="0.1" radius="0.05"/>
      </geometry>
      <origin xyz="0 0 0"/>
      <material name="blue"/>
    </visual>
    <collision>
      <geometry>
        <cylinder length="0.1" radius="0.05"/>
      </geometry>
      <origin xyz="0 0 0"/>
    </collision>
    <inertial>
      <mass value="1.0"/>
      <inertia ixx="0.00145833333333" ixy="0" ixz="0" iyy="0.00145833333333" iyz="0" izz="0.00125"/>
      <origin xyz="0 0 0"/>
    </inertial>
  </link>
  <joint name="base_link_to_fl_swerve_pivot" type="continuous">
    <parent link="base_link"/>
    <child link="fl_swerve_pivot"/>
    <axis xyz="0 0 1"/>
    <origin rpy="0 0 0" xyz="0.3048 0.3048 0.0"/>
  </joint>
  <transmission name="fl_swerve_pivot_trans">
    <type>transmission_interface/SimpleTransmission</type>
    <actuator name="fl_swerve_pivot_motor">
      <hardwareInterface>hardware_interface/PositionJointInterface</hardwareInterface>
      <mechanicalReduction>1</mechanicalReduction>
    </actuator>
    <joint name="base_link_to_fl_swerve_pivot">
      <hardwareInterface>hardware_interface/PositionJointInterface</hardwareInterface>
    </joint>
  </transmission>
  <gazebo reference="fl_swerve_pivot">
    <mu1 value="100.0"/>
    <mu2 value="100.0"/>
    <kp value="10000000.0"/>
    <kd value="1.0"/>
    <material>Gazebo/gray</material>
  </gazebo>
  <link name="fl_swerve_wheel">
    <visual>
      <geometry>
        <cylinder length="0.0381" radius="0.1016"/>
      </geometry>
      <origin xyz="0 0 0"/>
      <material name="blue"/>
    </visual>
    <collision>
      <geometry>
        <cylinder length="0.0381" radius="0.1016"/>
      </geometry>
      <origin xyz="0 0 0"/>
    </collision>
    <inertial>
      <mass value="1"/>
      <inertia ixx="0.0027016075" ixy="0" ixz="0" iyy="0.0027016075" iyz="0" izz="0.00516128"/>
      <origin xyz="0 0 0"/>
    </inertial>
  </link>
  <joint name="fl_swerve_pivot_to_fl_swerve_wheel" type="continuous">
    <parent link="fl_swerve_pivot"/>
    <child link="fl_swerve_wheel"/>
    <axis xyz="0 0 1"/>
    <origin rpy="-1.57079632679 0 0" xyz="0 0 0"/>
  </joint>
  <transmission name="fl_swerve_wheel_trans">
    <type>transmission_interface/SimpleTransmission</type>
    <actuator name="fl_swerve_wheel_motor">
      <hardwareInterface>hardware_interface/VelocityJointInterface</hardwareInterface>
      <mechanicalReduction>1</mechanicalReduction>
    </actuator>
    <joint name="fl_swerve_pivot_to_fl_swerve_wheel">
      <hardwareInterface>hardware_interface/VelocityJointInterface</hardwareInterface>
    </joint>
  </transmission>
  <gazebo reference="fl_swerve_wheel">
    <mu1 value="100.0"/>
    <mu2 value="100.0"/>
    <kp value="10000000.0"/>
    <kd value="1.0"/>
    <material>Gazebo/gray</material>
  </gazebo>
  <link name="rl_swerve_pivot">
    <visual>
      <geometry>
        <cylinder length="0.1" radius="0.05"/>
      </geometry>
      <origin xyz="0 0 0"/>
      <material name="blue"/>
    </visual>
    <collision>
      <geometry>
        <cylinder length="0.1" radius="0.05"/>
      </geometry>
      <origin xyz="0 0 0"/>
    </collision>
    <inertial>
      <mass value="1.0"/>
      <inertia ixx="0.00145833333333" ixy="0" ixz="0" iyy="0.00145833333333" iyz="0" izz="0.00125"/>
      <origin xyz="0 0 0"/>
    </inertial>
  </link>
  <joint name="base_link_to_rl_swerve_pivot" type="continuous">
    <parent link="base_link"/>
    <child link="rl_swerve_pivot"/>
    <axis xyz="0 0 1"/>
    <origin rpy="0 0 0" xyz="-0.3048 0.3048 0.0"/>
  </joint>
  <transmission name="rl_swerve_pivot_trans">
    <type>transmission_interface/SimpleTransmission</type>
    <actuator name="rl_swerve_pivot_motor">
      <hardwareInterface>hardware_interface/PositionJointInterface</hardwareInterface>
      <mechanicalReduction>1</mechanicalReduction>
    </actuator>
    <joint name="base_link_to_rl_swerve_pivot">
      <hardwareInterface>hardware_interface/PositionJointInterface</hardwareInterface>
    </joint>
  </transmission>
  <gazebo reference="rl_swerve_pivot">
    <mu1 value="100.0"/>
    <mu2 value="100.0"/>
    <kp value="10000000.0"/>
    <kd value="1.0"/>
    <material>Gazebo/gray</material>
  </gazebo>
  <link name="rl_swerve_wheel">
    <visual>
      <geometry>
        <cylinder length="0.0381" radius="0.1016"/>
      </geometry>
      <origin xyz="0 0 0"/>
      <material name="blue"/>
    </visual>
    <collision>
      <geometry>
        <cylinder length="0.0381" radius="0.1016"/>
      </geometry>
      <origin xyz="0 0 0"/>
    </collision>
    <inertial>
      <mass value="1"/>
      <inertia ixx="0.0027016075" ixy="0" ixz="0" iyy="0.0027016075" iyz="0" izz="0.00516128"/>
      <origin xyz="0 0 0"/>
    </inertial>
  </link>
  <joint name="rl_swerve_pivot_to_rl_swerve_wheel" type="continuous">
    <parent link="rl_swerve_pivot"/>
    <child link="rl_swerve_wheel"/>
    <axis xyz="0 0 1"/>
    <origin rpy="-1.57079632679 0 0" xyz="0 0 0"/>
  </joint>
  <transmission name="rl_swerve_wheel_trans">
    <type>transmission_interface/SimpleTransmission</type>
    <actuator name="rl_swerve_wheel_motor">
      <hardwareInterface>hardware_interface/VelocityJointInterface</hardwareInterface>
      <mechanicalReduction>1</mechanicalReduction>
    </actuator>
    <joint name="rl_swerve_pivot_to_rl_swerve_wheel">
      <hardwareInterface>hardware_interface/VelocityJointInterface</hardwareInterface>
    </joint>
  </transmission>
  <gazebo reference="rl_swerve_wheel">
    <mu1 value="100.0"/>
    <mu2 value="100.0"/>
    <kp value="10000000.0"/>
    <kd value="1.0"/>
    <material>Gazebo/gray</material>
  </gazebo>
  <link name="fr_swerve_pivot">
    <visual>
      <geometry>
        <cylinder length="0.1" radius="0.05"/>
      </geometry>
      <origin xyz="0 0 0"/>
      <material name="blue"/>
    </visual>
    <collision>
      <geometry>
        <cylinder length="0.1" radius="0.05"/>
      </geometry>
      <origin xyz="0 0 0"/>
    </collision>
    <inertial>
      <mass value="1.0"/>
      <inertia ixx="0.00145833333333" ixy="0" ixz="0" iyy="0.00145833333333" iyz="0" izz="0.00125"/>
      <origin xyz="0 0 0"/>
    </inertial>
  </link>
  <joint name="base_link_to_fr_swerve_pivot" type="continuous">
    <parent link="base_link"/>
    <child link="fr_swerve_pivot"/>
    <axis xyz="0 0 1"/>
    <origin rpy="0 0 0" xyz="0.3048 -0.3048 0.0"/>
  </joint>
  <transmission name="fr_swerve_pivot_trans">
    <type>transmission_interface/SimpleTransmission</type>
    <actuator name="fr_swerve_pivot_motor">
      <hardwareInterface>hardware_interface/PositionJointInterface</hardwareInterface>
      <mechanicalReduction>1</mechanicalReduction>
    </actuator>
    <joint name="base_link_to_fr_swerve_pivot">
      <hardwareInterface>hardware_interface/PositionJointInterface</hardwareInterface>
    </joint>
  </transmission>
  <gazebo reference="fr_swerve_pivot">
    <mu1 value="100.0"/>
    <mu2 value="100.0"/>
    <kp value="10000000.0"/>
    <kd value="1.0"/>
    <material>Gazebo/gray</material>
  </gazebo>
  <link name="fr_swerve_wheel">
    <visual>
      <geometry>
        <cylinder length="0.0381" radius="0.1016"/>
      </geometry>
      <origin xyz="0 0 0"/>
      <material name="blue"/>
    </visual>
    <collision>
      <geometry>
        <cylinder length="0.0381" radius="0.1016"/>
      </geometry>
      <origin xyz="0 0 0"/>
    </collision>
    <inertial>
      <mass value="1"/>
      <inertia ixx="0.0027016075" ixy="0" ixz="0" iyy="0.0027016075" iyz="0" izz="0.00516128"/>
      <origin xyz="0 0 0"/>
    </inertial>
  </link>
  <joint name="fr_swerve_pivot_to_fr_swerve_wheel" type="continuous">
    <parent link="fr_swerve_pivot"/>
    <child link="fr_swerve_wheel"/>
    <axis xyz="0 0 1"/>
    <origin rpy="-1.57079632679 0 0" xyz="0 0 0"/>
  </joint>
  <transmission name="fr_swerve_wheel_trans">
    <type>transmission_interface/SimpleTransmission</type>
    <actuator name="fr_swerve_wheel_motor">
      <hardwareInterface>hardware_interface/VelocityJointInterface</hardwareInterface>
      <mechanicalReduction>1</mechanicalReduction>
    </actuator>
    <joint name="fr_swerve_pivot_to_fr_swerve_wheel">
      <hardwareInterface>hardware_interface/VelocityJointInterface</hardwareInterface>
    </joint>
  </transmission>
  <gazebo reference="fr_swerve_wheel">
    <mu1 value="100.0"/>
    <mu2 value="100.0"/>
    <kp value="10000000.0"/>
    <kd value="1.0"/>
    <material>Gazebo/gray</material>
  </gazebo>
  <link name="rr_swerve_pivot">
    <visual>
      <geometry>
        <cylinder length="0.1" radius="0.05"/>
      </geometry>
      <origin xyz="0 0 0"/>
      <material name="blue"/>
    </visual>
    <collision>
      <geometry>
        <cylinder length="0.1" radius="0.05"/>
      </geometry>
      <origin xyz="0 0 0"/>
    </collision>
    <inertial>
      <mass value="1.0"/>
      <inertia ixx="0.00145833333333" ixy="0" ixz="0" iyy="0.00145833333333" iyz="0" izz="0.00125"/>
      <origin xyz="0 0 0"/>
    </inertial>
  </link>
  <joint name="base_link_to_rr_swerve_pivot" type="continuous">
    <parent link="base_link"/>
    <child link="rr_swerve_pivot"/>
    <axis xyz="0 0 1"/>
    <origin rpy="0 0 0" xyz="-0.3048 -0.3048 0.0"/>
  </joint>
  <transmission name="rr_swerve_pivot_trans">
    <type>transmission_interface/SimpleTransmission</type>
    <actuator name="rr_swerve_pivot_motor">
      <hardwareInterface>hardware_interface/PositionJointInterface</hardwareInterface>
      <mechanicalReduction>1</mechanicalReduction>
    </actuator>
    <joint name="base_link_to_rr_swerve_pivot">
      <hardwareInterface>hardware_interface/PositionJointInterface</hardwareInterface>
    </joint>
  </transmission>
  <gazebo reference="rr_swerve_pivot">
    <mu1 value="100.0"/>
    <mu2 value="100.0"/>
    <kp value="10000000.0"/>
    <kd value="1.0"/>
    <material>Gazebo/gray</material>
  </gazebo>
  <link name="rr_swerve_wheel">
    <visual>
      <geometry>
        <cylinder length="0.0381" radius="0.1016"/>
      </geometry>
      <origin xyz="0 0 0"/>
      <material name="blue"/>
    </visual>
    <collision>
      <geometry>
        <cylinder length="0.0381" radius="0.1016"/>
      </geometry>
      <origin xyz="0 0 0"/>
    </collision>
    <inertial>
      <mass value="1"/>
      <inertia ixx="0.0027016075" ixy="0" ixz="0" iyy="0.0027016075" iyz="0" izz="0.00516128"/>
      <origin xyz="0 0 0"/>
    </inertial>
  </link>
  <joint name="rr_swerve_pivot_to_rr_swerve_wheel" type="continuous">
    <parent link="rr_swerve_pivot"/>
    <child link="rr_swerve_wheel"/>
    <axis xyz="0 0 1"/>
    <origin rpy="-1.57079632679 0 0" xyz="0 0 0"/>
  </joint>
  <transmission name="rr_swerve_wheel_trans">
    <type>transmission_interface/SimpleTransmission</type>
    <actuator name="rr_swerve_wheel_motor">
      <hardwareInterface>hardware_interface/VelocityJointInterface</hardwareInterface>
      <mechanicalReduction>1</mechanicalReduction>
    </actuator>
    <joint name="rr_swerve_pivot_to_rr_swerve_wheel">
      <hardwareInterface>hardware_interface/VelocityJointInterface</hardwareInterface>
    </joint>
  </transmission>
  <gazebo reference="rr_swerve_wheel">
    <mu1 value="100.0"/>
    <mu2 value="100.0"/>
    <kp value="10000000.0"/>
    <kd value="1.0"/>
    <material>Gazebo/gray</material>
  </gazebo>
  <!-- <xacro:elevator_attachment name="elevator" parent="base_link"
    ax="0.0" ay="0.0" az="0.0762" rr="0.0" rp="0.0" ry="0.0"/> -->
  <!--                               Sensors                                -->
  <link name="kinect_mount"/>
  <joint name="base_link_to_kinect_mount" type="fixed">
    <parent link="base_link"/>
    <child link="kinect_mount"/>
    <origin rpy="0 0 0" xyz="0.25 0 0.2"/>
  </joint>
  <link name="lidar_mount"/>
  <joint name="kinect_mount_to_lidar_mount" type="fixed">
    <parent link="kinect_mount"/>
    <child link="lidar_mount"/>
    <origin rpy="0 0 0" xyz="0 0 0.1"/>
  </joint>
  <joint name="kinect_mount_to_camera_link" type="fixed">
    <parent link="kinect_mount"/>
    <child link="camera_link"/>
    <origin rpy="0 0 0" xyz="0 0 0"/>
  </joint>
  <link name="laser"/>
  <joint name="lidar_mount_to_laser" type="fixed">
    <parent link="lidar_mount"/>
    <child link="laser"/>
    <origin rpy="0 0 3.14159265359" xyz="0 0 0"/>
  </joint>
  <joint name="camera_rgb_joint" type="fixed">
    <origin rpy="0 0 0" xyz="0 0 0"/>
    <parent link="kinect_mount"/>
    <child link="camera_rgb_frame"/>
  </joint>
  <link name="camera_rgb_frame">
    <inertial>
      <mass value="0.001"/>
      <origin xyz="0 0 0"/>
      <inertia ixx="0.0001" ixy="0.0" ixz="0.0" iyy="0.0001" iyz="0.0" izz="0.0001"/>
    </inertial>
  </link>
  <joint name="camera_rgb_optical_joint" type="fixed">
    <origin rpy="-1.57079632679 0 -1.57079632679" xyz="0 0 0"/>
    <parent link="camera_rgb_frame"/>
    <child link="camera_rgb_optical_frame"/>
  </joint>
  <link name="camera_rgb_optical_frame">
    <inertial>
      <mass value="0.001"/>
      <origin xyz="0 0 0"/>
      <inertia ixx="0.0001" ixy="0.0" ixz="0.0" iyy="0.0001" iyz="0.0" izz="0.0001"/>
    </inertial>
  </link>
  <joint name="camera_joint" type="fixed">
    <origin rpy="0 0 0" xyz="-0.031 0 -0.016"/>
    <parent link="camera_rgb_frame"/>
    <child link="camera_link"/>
  </joint>
  <link name="camera_link">
    <visual>
      <origin rpy="0 0 1.57079632679" xyz="0 0 0"/>
      <geometry>
        <mesh filename="package://common_sensors/meshes/sensors/kinect.dae"/>
      </geometry>
    </visual>
    <collision>
      <origin rpy="0 0 0" xyz="0.0 0.0 0.0"/>
      <geometry>
        <box size="0.07271 0.27794 0.073"/>
      </geometry>
    </collision>
    <inertial>
      <mass value="0.001"/>
      <origin xyz="0 0 0"/>
      <inertia ixx="0.0001" ixy="0.0" ixz="0.0" iyy="0.0001" iyz="0.0" izz="0.0001"/>
    </inertial>
  </link>
  <!-- The fixed joints & links below are usually published by static_transformers launched by the OpenNi launch 
		 files. However, for Gazebo simulation we need them, so we add them here.
		 (Hence, don't publish them additionally!) -->
  <joint name="camera_depth_joint" type="fixed">
    <origin rpy="0 0 0" xyz="0 0 0"/>
    <parent link="camera_rgb_frame"/>
    <child link="camera_depth_frame"/>
  </joint>
  <link name="camera_depth_frame">
    <inertial>
      <mass value="0.001"/>
      <origin xyz="0 0 0"/>
      <inertia ixx="0.0001" ixy="0.0" ixz="0.0" iyy="0.0001" iyz="0.0" izz="0.0001"/>
    </inertial>
  </link>
  <joint name="camera_depth_optical_joint" type="fixed">
    <origin rpy="-1.57079632679 0 -1.57079632679" xyz="0 0 0"/>
    <parent link="camera_depth_frame"/>
    <child link="camera_depth_optical_frame"/>
  </joint>
  <link name="camera_depth_optical_frame">
    <inertial>
      <mass value="0.001"/>
      <origin xyz="0 0 0"/>
      <inertia ixx="0.0001" ixy="0.0" ixz="0.0" iyy="0.0001" iyz="0.0" izz="0.0001"/>
    </inertial>
  </link>
  <joint name="2D_Laser_joint" type="fixed">
    <axis xyz="0 1 0"/>
    <origin/>
    <parent link="lidar_mount"/>
    <child link="2D_Laser_link"/>
  </joint>
  <link name="2D_Laser_link">
    <inertial>
      <mass value="0.001"/>
      <origin rpy="0 0 0" xyz="0 0 0"/>
      <inertia ixx="0.0001" ixy="0" ixz="0" iyy="0.000001" iyz="0" izz="0.0001"/>
    </inertial>
    <visual>
      <origin rpy="0 0 0" xyz="0 0 0"/>
      <geometry>
        <mesh filename="package://common_sensors/meshes/sensors/hokuyo.dae" scale="0.024 0.024 0.024"/>
      </geometry>
    </visual>
    <collision>
      <!-- specifying a slightly too small collision surface because otherwise gazebo simulation catches on it -->
      <origin rpy="0 0 0" xyz="0 0 0.03"/>
      <geometry>
        <box size="0.02 0.02 0.06"/>
      </geometry>
    </collision>
  </link>
  <!-- go from the base of the laser to the actual sensor location -->
  <joint name="2D_Laser_laser_joint" type="fixed">
    <origin xyz="0 0 0.0525"/>
    <!-- in segbot package was 0.058 but looking at specs it is less -->
    <parent link="2D_Laser_link"/>
    <child link="2D_Laser_laser_link"/>
  </joint>
  <link name="2D_Laser_laser_link" type="laser">
    <inertial>
      <mass value="0.001"/>
      <origin rpy="0 0 0" xyz="0 0 0"/>
      <inertia ixx="0.0001" ixy="0" ixz="0" iyy="0.000001" iyz="0" izz="0.0001"/>
    </inertial>
  </link>
  <gazebo reference="2D_Laser_laser_link">
    <sensor name="2D_Laser_laser" type="ray">
      <always_on>true</always_on>
      <update_rate>10</update_rate>
      <pose>0 0 0 0 0 0</pose>
      <visualize>false</visualize>
      <ray>
        <scan>
          <horizontal>
            <samples>640</samples>
            <resolution>1</resolution>
            <min_angle>-2.0</min_angle>
            <max_angle>2.0</max_angle>
          </horizontal>
        </scan>
        <range>
          <min>0.02</min>
          <max>12.0</max>
          <resolution>0.03</resolution>
        </range>
      </ray>
      <plugin filename="libgazebo_ros_laser.so" name="gazebo_ros_2D_Laser_laser_controller">
        <gaussianNoise>0.0</gaussianNoise>
        <alwaysOn>true</alwaysOn>
        <updateRate>10</updateRate>
        <topicName>/scan</topicName>
        <frameName>2D_Laser_laser_link</frameName>
      </plugin>
    </sensor>
  </gazebo>
  <gazebo>
    <plugin filename="libgazebo_ros_imu.so" name="imu_plugin">
      <alwaysOn>true</alwaysOn>
      <bodyName>base_link</bodyName>
      <topicName>imu</topicName>
      <serviceName>imu_service</serviceName>
      <gaussianNoise>0.0</gaussianNoise>
      <updateRate>20.0</updateRate>
    </plugin>
  </gazebo>
  <!--                          For Gazebo Simulation                          -->
  <gazebo>
    <plugin filename="libgazebo_ros_control.so" name="gazebo_ros_control">
      <robotNamespace>/drivetrain</robotNamespace>
      <legacyModeNS>true</legacyModeNS>
    </plugin>
  </gazebo>
</robot>

