<sdf version='1.6'>
  <world name='default'>
    <light name='sun' type='directional'>
      <cast_shadows>1</cast_shadows>
      <pose frame=''>0 0 10 0 -0 0</pose>
      <diffuse>0.8 0.8 0.8 1</diffuse>
      <specular>0.1 0.1 0.1 1</specular>
      <attenuation>
        <range>1000</range>
        <constant>0.9</constant>
        <linear>0.01</linear>
        <quadratic>0.001</quadratic>
      </attenuation>
      <direction>-0.5 0.5 -1</direction>
    </light>
    <model name='ground_plane'>
      <static>1</static>
      <link name='link'>
        <collision name='collision'>
          <geometry>
            <plane>
              <normal>0 0 1</normal>
              <size>100 100</size>
            </plane>
          </geometry>
          <surface>
            <friction>
              <ode>
                <mu>100</mu>
                <mu2>50</mu2>
              </ode>
              <torsional>
                <ode/>
              </torsional>
            </friction>
            <contact>
              <ode/>
            </contact>
            <bounce/>
          </surface>
          <max_contacts>10</max_contacts>
        </collision>
        <visual name='visual'>
          <cast_shadows>0</cast_shadows>
          <geometry>
            <plane>
              <normal>0 0 1</normal>
              <size>100 100</size>
            </plane>
          </geometry>
          <material>
            <script>
              <uri>file://media/materials/scripts/gazebo.material</uri>
              <name>Gazebo/Grey</name>
            </script>
          </material>
        </visual>
        <self_collide>0</self_collide>
        <kinematic>0</kinematic>
        <gravity>1</gravity>
      </link>
    </model>
    <gravity>0 0 -9.8</gravity>
    <magnetic_field>6e-06 2.3e-05 -4.2e-05</magnetic_field>
    <atmosphere type='adiabatic'/>
    <physics name='default_physics' default='0' type='ode'>
      <max_step_size>0.001</max_step_size>
      <real_time_factor>1</real_time_factor>
      <real_time_update_rate>1000</real_time_update_rate>
    </physics>
    <scene>
      <ambient>0.4 0.4 0.4 1</ambient>
      <background>0.7 0.7 0.7 1</background>
      <shadows>1</shadows>
    </scene>
    <spherical_coordinates>
      <surface_model>EARTH_WGS84</surface_model>
      <latitude_deg>0</latitude_deg>
      <longitude_deg>0</longitude_deg>
      <elevation>0</elevation>
      <heading_deg>0</heading_deg>
    </spherical_coordinates>
    <model name='frc2016_field'>
      <static>1</static>
      <link name='walls'>
        <visual name='walls_visual'>
          <geometry>
            <mesh>
              <uri>model://frc2016_field/meshes/walls.dae</uri>
              <scale>1 1 1</scale>
            </mesh>
          </geometry>
        </visual>
        <collision name='front_turret'>
          <geometry>
            <mesh>
              <uri>model://frc2016_field/meshes/turret_collide.dae</uri>
              <scale>1 1 1</scale>
            </mesh>
          </geometry>
          <max_contacts>10</max_contacts>
          <surface>
            <contact>
              <ode/>
            </contact>
            <bounce/>
            <friction>
              <torsional>
                <ode/>
              </torsional>
              <ode/>
            </friction>
          </surface>
        </collision>
        <collision name='back_turret'>
          <pose frame=''>0 0 0 0 -0 3.1415</pose>
          <geometry>
            <mesh>
              <uri>model://frc2016_field/meshes/turret_collide.dae</uri>
              <scale>1 1 1</scale>
            </mesh>
          </geometry>
          <max_contacts>10</max_contacts>
          <surface>
            <contact>
              <ode/>
            </contact>
            <bounce/>
            <friction>
              <torsional>
                <ode/>
              </torsional>
              <ode/>
            </friction>
          </surface>
        </collision>
        <collision name='left_wall'>
          <pose frame=''>4.09997 0 0.2413 0 -0 0</pose>
          <geometry>
            <box>
              <size>0.1 16.4592 0.4826</size>
            </box>
          </geometry>
          <max_contacts>10</max_contacts>
          <surface>
            <contact>
              <ode/>
            </contact>
            <bounce/>
            <friction>
              <torsional>
                <ode/>
              </torsional>
              <ode/>
            </friction>
          </surface>
        </collision>
        <collision name='right_wall'>
          <pose frame=''>-4.09997 0 0.2413 0 -0 0</pose>
          <geometry>
            <box>
              <size>0.1 16.4592 0.4826</size>
            </box>
          </geometry>
          <max_contacts>10</max_contacts>
          <surface>
            <contact>
              <ode/>
            </contact>
            <bounce/>
            <friction>
              <torsional>
                <ode/>
              </torsional>
              <ode/>
            </friction>
          </surface>
        </collision>
        <collision name='front_solid_wall'>
          <pose frame=''>-2.2105 8.2196 1 0 -0 0</pose>
          <geometry>
            <box>
              <size>3.8 0.1 2</size>
            </box>
          </geometry>
          <max_contacts>10</max_contacts>
          <surface>
            <contact>
              <ode/>
            </contact>
            <bounce/>
            <friction>
              <torsional>
                <ode/>
              </torsional>
              <ode/>
            </friction>
          </surface>
        </collision>
        <collision name='back_solid_wall'>
          <pose frame=''>2.2105 -8.2196 1 0 -0 0</pose>
          <geometry>
            <box>
              <size>3.8 0.1 2</size>
            </box>
          </geometry>
          <max_contacts>10</max_contacts>
          <surface>
            <contact>
              <ode/>
            </contact>
            <bounce/>
            <friction>
              <torsional>
                <ode/>
              </torsional>
              <ode/>
            </friction>
          </surface>
        </collision>
        <collision name='front_partial_wall'>
          <pose frame=''>1.85 8.2196 1 0 -0 0</pose>
          <geometry>
            <box>
              <size>2.1 0.1 2</size>
            </box>
          </geometry>
          <max_contacts>10</max_contacts>
          <surface>
            <contact>
              <ode/>
            </contact>
            <bounce/>
            <friction>
              <torsional>
                <ode/>
              </torsional>
              <ode/>
            </friction>
          </surface>
        </collision>
        <collision name='front_partial_wall_mid'>
          <pose frame=''>3.4 8.2196 0.86 0 -0 0</pose>
          <geometry>
            <box>
              <size>1.25 0.1 1.12</size>
            </box>
          </geometry>
          <max_contacts>10</max_contacts>
          <surface>
            <contact>
              <ode/>
            </contact>
            <bounce/>
            <friction>
              <torsional>
                <ode/>
              </torsional>
              <ode/>
            </friction>
          </surface>
        </collision>
        <collision name='front_partial_wall_lower_left'>
          <pose frame=''>3.36 8.2196 0.25 0 -0 0</pose>
          <geometry>
            <box>
              <size>0.3 0.1 0.5</size>
            </box>
          </geometry>
          <max_contacts>10</max_contacts>
          <surface>
            <contact>
              <ode/>
            </contact>
            <bounce/>
            <friction>
              <torsional>
                <ode/>
              </torsional>
              <ode/>
            </friction>
          </surface>
        </collision>
        <collision name='front_partial_wall_lower_right'>
          <pose frame=''>4 8.2196 0.25 0 -0 0</pose>
          <geometry>
            <box>
              <size>0.3 0.1 0.5</size>
            </box>
          </geometry>
          <max_contacts>10</max_contacts>
          <surface>
            <contact>
              <ode/>
            </contact>
            <bounce/>
            <friction>
              <torsional>
                <ode/>
              </torsional>
              <ode/>
            </friction>
          </surface>
        </collision>
        <collision name='front_partial_wall_upper_right'>
          <pose frame=''>3.76 8.2196 1.7 0 -0 0</pose>
          <geometry>
            <box>
              <size>0.54 0.1 0.6</size>
            </box>
          </geometry>
          <max_contacts>10</max_contacts>
          <surface>
            <contact>
              <ode/>
            </contact>
            <bounce/>
            <friction>
              <torsional>
                <ode/>
              </torsional>
              <ode/>
            </friction>
          </surface>
        </collision>
        <collision name='front_partial_wall_upper_left'>
          <pose frame=''>2.95 8.2196 1.7 0 -0 0</pose>
          <geometry>
            <box>
              <size>0.54 0.1 0.6</size>
            </box>
          </geometry>
          <max_contacts>10</max_contacts>
          <surface>
            <contact>
              <ode/>
            </contact>
            <bounce/>
            <friction>
              <torsional>
                <ode/>
              </torsional>
              <ode/>
            </friction>
          </surface>
        </collision>
        <collision name='front_partial_wall_upper_mid'>
          <pose frame=''>3.36 8.2196 1.84 0 -0 0</pose>
          <geometry>
            <box>
              <size>0.3 0.1 0.3</size>
            </box>
          </geometry>
          <max_contacts>10</max_contacts>
          <surface>
            <contact>
              <ode/>
            </contact>
            <bounce/>
            <friction>
              <torsional>
                <ode/>
              </torsional>
              <ode/>
            </friction>
          </surface>
        </collision>
        <collision name='back_partial_wall'>
          <pose frame=''>-1.85 -8.2196 1 0 -0 0</pose>
          <geometry>
            <box>
              <size>2.1 0.1 2</size>
            </box>
          </geometry>
          <max_contacts>10</max_contacts>
          <surface>
            <contact>
              <ode/>
            </contact>
            <bounce/>
            <friction>
              <torsional>
                <ode/>
              </torsional>
              <ode/>
            </friction>
          </surface>
        </collision>
        <collision name='back_partial_wall_mid'>
          <pose frame=''>-3.4 -8.2196 0.86 0 -0 0</pose>
          <geometry>
            <box>
              <size>1.25 0.1 1.12</size>
            </box>
          </geometry>
          <max_contacts>10</max_contacts>
          <surface>
            <contact>
              <ode/>
            </contact>
            <bounce/>
            <friction>
              <torsional>
                <ode/>
              </torsional>
              <ode/>
            </friction>
          </surface>
        </collision>
        <collision name='back_partial_wall_lower_left'>
          <pose frame=''>-3.36 -8.2196 0.25 0 -0 0</pose>
          <geometry>
            <box>
              <size>0.3 0.1 0.5</size>
            </box>
          </geometry>
          <max_contacts>10</max_contacts>
          <surface>
            <contact>
              <ode/>
            </contact>
            <bounce/>
            <friction>
              <torsional>
                <ode/>
              </torsional>
              <ode/>
            </friction>
          </surface>
        </collision>
        <collision name='back_partial_wall_lower_right'>
          <pose frame=''>-4 -8.2196 0.25 0 -0 0</pose>
          <geometry>
            <box>
              <size>0.3 0.1 0.5</size>
            </box>
          </geometry>
          <max_contacts>10</max_contacts>
          <surface>
            <contact>
              <ode/>
            </contact>
            <bounce/>
            <friction>
              <torsional>
                <ode/>
              </torsional>
              <ode/>
            </friction>
          </surface>
        </collision>
        <collision name='back_partial_wall_upper_right'>
          <pose frame=''>-3.76 -8.2196 1.7 0 -0 0</pose>
          <geometry>
            <box>
              <size>0.54 0.1 0.6</size>
            </box>
          </geometry>
          <max_contacts>10</max_contacts>
          <surface>
            <contact>
              <ode/>
            </contact>
            <bounce/>
            <friction>
              <torsional>
                <ode/>
              </torsional>
              <ode/>
            </friction>
          </surface>
        </collision>
        <collision name='back_partial_wall_upper_left'>
          <pose frame=''>-2.95 -8.2196 1.7 0 -0 0</pose>
          <geometry>
            <box>
              <size>0.54 0.1 0.6</size>
            </box>
          </geometry>
          <max_contacts>10</max_contacts>
          <surface>
            <contact>
              <ode/>
            </contact>
            <bounce/>
            <friction>
              <torsional>
                <ode/>
              </torsional>
              <ode/>
            </friction>
          </surface>
        </collision>
        <collision name='back_partial_wall_upper_mid'>
          <pose frame=''>-3.36 -8.2196 1.84 0 -0 0</pose>
          <geometry>
            <box>
              <size>0.3 0.1 0.3</size>
            </box>
          </geometry>
          <max_contacts>10</max_contacts>
          <surface>
            <contact>
              <ode/>
            </contact>
            <bounce/>
            <friction>
              <torsional>
                <ode/>
              </torsional>
              <ode/>
            </friction>
          </surface>
        </collision>
        <visual name='blue_passage_border_long'>
          <pose frame=''>2.72665 4.5882 0.0127 0 -0 0</pose>
          <geometry>
            <box>
              <size>0.0762 7.3025 0.0254</size>
            </box>
          </geometry>
          <material>
            <ambient>0 0 1 1</ambient>
            <diffuse>0 0 1 1</diffuse>
          </material>
        </visual>
        <visual name='blue_passage_border_short'>
          <pose frame=''>3.37435 0.97352 0.0127 0 -0 0</pose>
          <geometry>
            <box>
              <size>1.37165 0.0762 0.0254</size>
            </box>
          </geometry>
          <material>
            <ambient>0 0 1 1</ambient>
            <diffuse>0 0 1 1</diffuse>
          </material>
        </visual>
        <visual name='blue_divider_1'>
          <pose frame=''>2.63052 2.80648 0.31114 0 -0 0</pose>
          <geometry>
            <box>
              <size>0.009525 1.2192 0.6096</size>
            </box>
          </geometry>
        </visual>
        <collision name='blue_divider_1'>
          <pose frame=''>2.63052 2.80648 0.31114 0 -0 0</pose>
          <geometry>
            <box>
              <size>0.009525 1.2192 0.6096</size>
            </box>
          </geometry>
          <max_contacts>10</max_contacts>
          <surface>
            <contact>
              <ode/>
            </contact>
            <bounce/>
            <friction>
              <torsional>
                <ode/>
              </torsional>
              <ode/>
            </friction>
          </surface>
        </collision>
        <visual name='blue_divider_2'>
          <pose frame=''>1.28432 2.80648 0.31114 0 -0 0</pose>
          <geometry>
            <box>
              <size>0.009525 1.2192 0.6096</size>
            </box>
          </geometry>
        </visual>
        <collision name='blue_divider_2'>
          <pose frame=''>1.28432 2.80648 0.31114 0 -0 0</pose>
          <geometry>
            <box>
              <size>0.009525 1.2192 0.6096</size>
            </box>
          </geometry>
          <max_contacts>10</max_contacts>
          <surface>
            <contact>
              <ode/>
            </contact>
            <bounce/>
            <friction>
              <torsional>
                <ode/>
              </torsional>
              <ode/>
            </friction>
          </surface>
        </collision>
        <visual name='blue_divider_3'>
          <pose frame=''>-0.06189 2.80648 0.31114 0 -0 0</pose>
          <geometry>
            <box>
              <size>0.009525 1.2192 0.6096</size>
            </box>
          </geometry>
        </visual>
        <collision name='blue_divider_3'>
          <pose frame=''>-0.06189 2.80648 0.31114 0 -0 0</pose>
          <geometry>
            <box>
              <size>0.009525 1.2192 0.6096</size>
            </box>
          </geometry>
          <max_contacts>10</max_contacts>
          <surface>
            <contact>
              <ode/>
            </contact>
            <bounce/>
            <friction>
              <torsional>
                <ode/>
              </torsional>
              <ode/>
            </friction>
          </surface>
        </collision>
        <visual name='blue_divider_4'>
          <pose frame=''>-1.40809 2.80648 0.31114 0 -0 0</pose>
          <geometry>
            <box>
              <size>0.009525 1.2192 0.6096</size>
            </box>
          </geometry>
        </visual>
        <collision name='blue_divider_4'>
          <pose frame=''>-1.40809 2.80648 0.31114 0 -0 0</pose>
          <geometry>
            <box>
              <size>0.009525 1.2192 0.6096</size>
            </box>
          </geometry>
          <max_contacts>10</max_contacts>
          <surface>
            <contact>
              <ode/>
            </contact>
            <bounce/>
            <friction>
              <torsional>
                <ode/>
              </torsional>
              <ode/>
            </friction>
          </surface>
        </collision>
        <visual name='blue_divider_5'>
          <pose frame=''>-2.75428 2.80648 0.31114 0 -0 0</pose>
          <geometry>
            <box>
              <size>0.009525 1.2192 0.6096</size>
            </box>
          </geometry>
        </visual>
        <collision name='blue_divider_5'>
          <pose frame=''>-2.75428 2.80648 0.31114 0 -0 0</pose>
          <geometry>
            <box>
              <size>0.009525 1.2192 0.6096</size>
            </box>
          </geometry>
          <max_contacts>10</max_contacts>
          <surface>
            <contact>
              <ode/>
            </contact>
            <bounce/>
            <friction>
              <torsional>
                <ode/>
              </torsional>
              <ode/>
            </friction>
          </surface>
        </collision>
        <visual name='blue_barrier_ramp_up'>
          <pose frame=''>-0.7334 3.22301 0.05063 -0.248866 0 0</pose>
          <geometry>
            <box>
              <size>6.71817 0.3048 0.00635</size>
            </box>
          </geometry>
        </visual>
        <collision name='blue_barrier_ramp_up'>
          <pose frame=''>-0.7334 3.22301 0.05063 -0.248866 0 0</pose>
          <geometry>
            <box>
              <size>6.71817 0.3048 0.00635</size>
            </box>
          </geometry>
          <max_contacts>10</max_contacts>
          <surface>
            <contact>
              <ode/>
            </contact>
            <bounce/>
            <friction>
              <torsional>
                <ode/>
              </torsional>
              <ode/>
            </friction>
          </surface>
        </collision>
        <visual name='blue_barrier_ramp_down'>
          <pose frame=''>-0.7334 2.31802 0.05063 0.248866 -0 0</pose>
          <geometry>
            <box>
              <size>6.71817 0.3048 0.00635</size>
            </box>
          </geometry>
        </visual>
        <collision name='blue_barrier_ramp_down'>
          <pose frame=''>-0.7334 2.31802 0.05063 0.248866 -0 0</pose>
          <geometry>
            <box>
              <size>6.71817 0.3048 0.00635</size>
            </box>
          </geometry>
          <max_contacts>10</max_contacts>
          <surface>
            <contact>
              <ode/>
            </contact>
            <bounce/>
            <friction>
              <torsional>
                <ode/>
              </torsional>
              <ode/>
            </friction>
          </surface>
        </collision>
        <visual name='red_passage_border_long'>
          <pose frame=''>-2.7273 -4.58839 0.0127 0 -0 0</pose>
          <geometry>
            <box>
              <size>0.0762 7.3025 0.0254</size>
            </box>
          </geometry>
          <material>
            <ambient>1 0 0 1</ambient>
            <diffuse>1 0 0 1</diffuse>
          </material>
        </visual>
        <visual name='red_passage_border_short'>
          <pose frame=''>-3.375 -0.97372 0.0127 0 -0 0</pose>
          <geometry>
            <box>
              <size>1.37165 0.0762 0.0254</size>
            </box>
          </geometry>
          <material>
            <ambient>1 0 0 1</ambient>
            <diffuse>1 0 0 1</diffuse>
          </material>
        </visual>/home/jake/catkin_ws/src/frc_robot/launch/sim.launch
        <visual name='red_divider_1'>
          <pose frame=''>-2.63117 -2.76442 0.31114 0 -0 0</pose>
          <geometry>
            <box>
              <size>0.009525 1.2192 0.6096</size>
            </box>
          </geometry>
        </visual>
        <collision name='red_divider_1'>
          <pose frame=''>-2.63117 -2.72845 0.31114 0 -0 0</pose>
          <geometry>
            <box>
              <size>0.009525 1.2192 0.6096</size>
            </box>
          </geometry>
          <max_contacts>10</max_contacts>
          <surface>
            <contact>
              <ode/>
            </contact>
            <bounce/>
            <friction>
              <torsional>
                <ode/>
              </torsional>
              <ode/>
            </friction>
          </surface>
        </collision>
        <visual name='red_divider_2'>
          <pose frame=''>-1.28496 -2.76442 0.31114 0 -0 0</pose>
          <geometry>
            <box>
              <size>0.009525 1.2192 0.6096</size>
            </box>
          </geometry>
        </visual>
        <collision name='red_divider_2'>
          <pose frame=''>-1.28496 -2.76442 0.31114 0 -0 0</pose>
          <geometry>
            <box>
              <size>0.009525 1.2192 0.6096</size>
            </box>
          </geometry>
          <max_contacts>10</max_contacts>
          <surface>
            <contact>
              <ode/>
            </contact>
            <bounce/>
            <friction>
              <torsional>
                <ode/>
              </torsional>
              <ode/>
            </friction>
          </surface>
        </collision>
        <visual name='red_divider_3'>
          <pose frame=''>0.06124 -2.76442 0.31114 0 -0 0</pose>
          <geometry>
            <box>
              <size>0.009525 1.2192 0.6096</size>
            </box>
          </geometry>
        </visual>
        <collision name='red_divider_3'>
          <pose frame=''>0.06124 -2.76442 0.31114 0 -0 0</pose>
          <geometry>
            <box>
              <size>0.009525 1.2192 0.6096</size>
            </box>
          </geometry>
          <max_contacts>10</max_contacts>
          <surface>
            <contact>
              <ode/>
            </contact>
            <bounce/>
            <friction>
              <torsional>
                <ode/>
              </torsional>
              <ode/>
            </friction>
          </surface>
        </collision>
        <visual name='red_divider_4'>
          <pose frame=''>1.40744 -2.76442 0.31114 0 -0 0</pose>
          <geometry>
            <box>
              <size>0.009525 1.2192 0.6096</size>
            </box>
          </geometry>
        </visual>
        <collision name='red_divider_4'>
          <pose frame=''>1.40744 -2.76442 0.31114 0 -0 0</pose>
          <geometry>
            <box>
              <size>0.009525 1.2192 0.6096</size>
            </box>
          </geometry>
          <max_contacts>10</max_contacts>
          <surface>
            <contact>
              <ode/>
            </contact>
            <bounce/>
            <friction>
              <torsional>
                <ode/>
              </torsional>
              <ode/>
            </friction>
          </surface>
        </collision>
        <visual name='red_divider_5'>
          <pose frame=''>2.75363 -2.76442 0.31114 0 -0 0</pose>
          <geometry>
            <box>
              <size>0.009525 1.2192 0.6096</size>
            </box>
          </geometry>
        </visual>
        <collision name='red_divider_5'>
          <pose frame=''>2.75363 -2.76442 0.31114 0 -0 0</pose>
          <geometry>
            <box>
              <size>0.009525 1.2192 0.6096</size>
            </box>
          </geometry>
          <max_contacts>10</max_contacts>
          <surface>
            <contact>
              <ode/>
            </contact>
            <bounce/>
            <friction>
              <torsional>
                <ode/>
              </torsional>
              <ode/>
            </friction>
          </surface>
        </collision>
        <visual name='red_barrier_ramp_down'>
          <pose frame=''>0.73275 -2.31261 0.05063 -0.248866 0 0</pose>
          <geometry>
            <box>
              <size>6.71817 0.3048 0.00635</size>
            </box>
          </geometry>
        </visual>
        <collision name='red_barrier_ramp_down'>
          <pose frame=''>0.73275 -2.31261 0.05063 -0.248866 0 0</pose>
          <geometry>
            <box>
              <size>6.71817 0.3048 0.00635</size>
            </box>
          </geometry>
          <max_contacts>10</max_contacts>
          <surface>
            <contact>
              <ode/>
            </contact>
            <bounce/>
            <friction>
              <torsional>
                <ode/>
              </torsional>
              <ode/>
            </friction>
          </surface>
        </collision>
        <visual name='red_barrier_ramp_up'>
          <pose frame=''>0.73275 -3.21691 0.05063 0.248866 -0 0</pose>
          <geometry>
            <box>
              <size>6.71817 0.3048 0.00635</size>
            </box>
          </geometry>
        </visual>
        <collision name='red_barrier_ramp_up'>
          <pose frame=''>0.73275 -3.21691 0.05063 0.248866 -0 0</pose>
          <geometry>
            <box>
              <size>6.71817 0.3048 0.00635</size>
            </box>
          </geometry>
          <max_contacts>10</max_contacts>
          <surface>
            <contact>
              <ode/>
            </contact>
            <bounce/>
            <friction>
              <torsional>
                <ode/>
              </torsional>
              <ode/>
            </friction>
          </surface>
        </collision>
        <self_collide>0</self_collide>
        <kinematic>0</kinematic>
        <gravity>1</gravity>
      </link>
      <pose frame=''>0.061261 -0.112048 0 0 -0 0</pose>
    </model>
    <state world_name='default'>
      <sim_time>2732 517000000</sim_time>
      <real_time>1602 695771965</real_time>
      <wall_time>1562639172 147137792</wall_time>
      <iterations>1577041</iterations>
      <model name='frc2016_chevaldefrise'>
        <pose frame=''>3.411 -2.72547 1e-06 5e-06 -0 2.7e-05</pose>
        <scale>1 1 1</scale>
        <link name='base'>
          <pose frame=''>3.411 -2.72547 1e-06 5e-06 -0 2.7e-05</pose>
          <velocity>2e-06 0 0.002881 -0.010678 -0.004339 -8e-06</velocity>
          <acceleration>-0.763506 3.30961 4.96573 2.09353 -0.695483 -0.337561</acceleration>
          <wrench>-7.63506 33.0961 49.6573 0 -0 0</wrench>
        </link>
        <link name='slant1'>
          <pose frame=''>2.95379 -2.71241 0.199701 -0.372316 -1e-06 2.6e-05</pose>
          <velocity>-0.000744 0.00221 0.000738 0.022259 -0.004992 -0.000628</velocity>
          <acceleration>-0.908904 4.97028 5.14593 -1.64093 1.12474 -0.343278</acceleration>
          <wrench>-1.81781 9.94056 10.2919 0 -0 0</wrench>
        </link>
        <link name='slant2'>
          <pose frame=''>3.2586 -2.73854 0.199701 0.397356 0 2.7e-05</pose>
          <velocity>-0.00083 0.002161 0.002352 0.031367 -0.004375 -0.000139</velocity>
          <acceleration>-0.480628 5.08728 1.42512 -0.649272 0.679272 -1.34587</acceleration>
          <wrench>-0.961257 10.1746 2.85024 0 -0 0</wrench>
        </link>
        <link name='slant3'>
          <pose frame=''>3.56339 -2.71239 0.199701 -0.37233 -1e-06 2.7e-05</pose>
          <velocity>-0.000769 0.002161 0.003392 0.018521 -0.004979 -0.000724</velocity>
          <acceleration>-0.919272 6.26688 9.6513 1.91107 1.06892 -0.271459</acceleration>
          <wrench>-1.83854 12.5338 19.3026 0 -0 0</wrench>
        </link>
        <link name='slant4'>
          <pose frame=''>3.8682 -2.73853 0.199701 0.397342 -0 2.7e-05</pose>
          <velocity>-0.000837 0.00208 0.005019 -0.014978 -0.004373 -0.000126</velocity>
          <acceleration>-0.487272 4.68385 11.6323 3.1391 0.651698 -1.31926</acceleration>
          <wrench>-0.974543 9.36771 23.2647 0 -0 0</wrench>
        </link>
      </model>
      <model name='frc2016_chevaldefrise_clone'>
        <pose frame=''>-0.765476 2.78685 0 0 0 -9.7e-05</pose>
        <scale>1 1 1</scale>
        <link name='base'>
          <pose frame=''>-0.765476 2.78685 0 0 0 -9.7e-05</pose>
          <velocity>0 0 0 0 -0 0</velocity>
          <acceleration>-1e-06 -4e-06 1e-06 2.4e-05 -8e-06 0</acceleration>
          <wrench>-1.2e-05 -3.8e-05 5e-06 0 -0 0</wrench>
        </link>
        <link name='slant1'>
          <pose frame=''>-1.22267 2.79996 0.1997 -0.39732 -0 -9.7e-05</pose>
          <velocity>0 0 0 0 -0 0</velocity>
          <acceleration>-1e-06 -6e-06 -5e-06 -2.5e-05 -7e-06 2e-06</acceleration>
          <wrench>-2e-06 -1.2e-05 -1e-05 0 -0 0</wrench>
        </link>
        <link name='slant2'>
          <pose frame=''>-0.917877 2.77379 0.1997 0.39732 -0 -9.7e-05</pose>
          <velocity>0 0 0 -3e-06 0 0</velocity>
          <acceleration>-1e-06 2.3e-05 -6.9e-05 0.000734 -7e-06 -2e-06</acceleration>
          <wrench>-2e-06 4.7e-05 -0.000137 0 -0 0</wrench>
        </link>
        <link name='slant3'>
          <pose frame=''>-0.613075 2.7999 0.1997 -0.39732 -0 -9.7e-05</pose>
          <velocity>0 0 0 2.6e-05 -0 0</velocity>
          <acceleration>-1e-06 -0.00026 -0.000605 -0.006587 -8e-06 3e-06</acceleration>
          <wrench>-2e-06 -0.00052 -0.001211 0 -0 0</wrench>
        </link>
        <link name='slant4'>
          <pose frame=''>-0.308277 2.77373 0.1997 0.397342 -0 -9.7e-05</pose>
          <velocity>0 0 0 0.0224 -2e-06 -0</velocity>
          <acceleration>8.2e-05 0.86674 -2.06546 -2.73324 0.003692 0.001907</acceleration>
          <wrench>0.000165 1.73348 -4.13091 0 -0 0</wrench>
        </link>
      </model>
      <model name='frc2016_drawbridge'>
        <pose frame=''>-1.94863 -2.76098 0 0 -0 0.002829</pose>
        <scale>1 1 1</scale>
        <link name='base'>
          <pose frame=''>-1.94863 -2.76098 0 0 -0 0.002829</pose>
          <velocity>0 0 0.00679 0.001921 0.000318 -0</velocity>
          <acceleration>0.499123 -1.73777 14.755 1.77881 0.383426 -0.086451</acceleration>
          <wrench>4.99123 -17.3777 147.55 0 -0 0</wrench>
        </link>
        <link name='bridge'>
          <pose frame=''>-1.94943 -2.47854 0.50577 8e-06 -0 0.002828</pose>
          <velocity>0.000151 6.5e-05 0.007355 -0.000124 0.000246 0.000285</velocity>
          <acceleration>0.089622 0.174847 14.1751 -2.46966 0.411154 -0.157809</acceleration>
          <wrench>0.179244 0.349694 28.3502 0 -0 0</wrench>
        </link>
      </model>
      <model name='frc2016_drawbridge_clone'>
        <pose frame=''>1.96524 2.77507 -3e-06 1e-06 4e-06 0.001216</pose>
        <scale>1 1 1</scale>
        <link name='base'>
          <pose frame=''>1.96524 2.77507 -3e-06 1e-06 4e-06 0.001216</pose>
          <velocity>0.000139 0.000297 -0.003489 0.001613 0.004839 0.000467</velocity>
          <acceleration>1.65488 -0.800263 -6.61982 0.892955 1.52974 0.196517</acceleration>
          <wrench>16.5488 -8.00263 -66.1983 0 -0 0</wrench>
        </link>
        <link name='bridge'>
          <pose frame=''>1.9649 3.05752 0.505767 2e-06 4e-06 0.001216</pose>
          <velocity>0.002485 -0.000482 -0.003034 0.001475 0.004827 0.000405</velocity>
          <acceleration>0.096213 -0.163319 -6.6224 0.732065 1.54662 -0.086773</acceleration>
          <wrench>0.192426 -0.326638 -13.2448 0 -0 0</wrench>
        </link>
      </model>
      <model name='frc2016_field'>
        <pose frame=''>0 0 0 0 -0 0</pose>
        <scale>1 1 1</scale>
        <link name='walls'>
          <pose frame=''>0 0 0 0 -0 0</pose>
          <velocity>0 0 0 0 -0 0</velocity>
          <acceleration>0 0 0 0 -0 0</acceleration>
          <wrench>0 0 0 0 -0 0</wrench>
        </link>
      </model>
      <model name='frc2016_lowbar'>
        <pose frame=''>-0.638919 -2.77936 -5e-06 2.5e-05 4e-06 0.014383</pose>
        <scale>1 1 1</scale>
        <link name='base'>
          <pose frame=''>-0.638919 -2.77936 -5e-06 2.5e-05 4e-06 0.014383</pose>
          <velocity>1.9e-05 2e-06 0.000683 0.020589 -0.004604 1.5e-05</velocity>
          <acceleration>0.000873 0.004625 2.04136 0.193009 -0.119341 -0.011481</acceleration>
          <wrench>0.043639 0.231237 102.068 0 -0 0</wrench>
        </link>
        <link name='wall'>
          <pose frame=''>-0.63636 -2.95719 0.243219 -8.7e-05 6e-06 0.014383</pose>
          <velocity>-0.001133 -0.004109 -0.003126 0.024072 -0.004916 -3.2e-05</velocity>
          <acceleration>-4.73845 -0.546725 -0.522984 -0.03328 -0.698797 -0.122899</acceleration>
          <wrench>-4.73845 -0.546725 -0.522984 0 -0 0</wrench>
        </link>
      </model>
      <model name='frc2016_lowbar_clone'>
        <pose frame=''>-2.11147 2.7836 -2.5e-05 0 -3.9e-05 -0.002925</pose>
        <scale>1 1 1</scale>
        <link name='base'>
          <pose frame=''>-2.11147 2.7836 -2.5e-05 0 -3.9e-05 -0.002925</pose>
          <velocity>5.6e-05 -0.000113 -0.008826 -8.6e-05 -0.029648 0.000114</velocity>
          <acceleration>-0.037864 -0.003814 -9.44821 -1.02805 1.3881 -3.00791</acceleration>
          <wrench>-1.89318 -0.190713 -472.41 0 -0 0</wrench>
        </link>
        <link name='wall'>
          <pose frame=''>-2.11196 2.62034 0.243495 0.039996 -3.2e-05 -0.002924</pose>
          <velocity>-0.007605 -0.127294 -0.013651 -0.349263 -0.030376 -7.7e-05</velocity>
          <acceleration>-8.987 -0.090671 -9.1613 -0.511166 -1.4052 -0.133487</acceleration>
          <wrench>-8.987 -0.090671 -9.1613 0 -0 0</wrench>
        </link>
      </model>
      <model name='frc2016_portcullis'>
        <pose frame=''>0.734192 -2.7602 0 0 -0 0.078609</pose>
        <scale>1 1 1</scale>
        <link name='base'>
          <pose frame=''>0.734192 -2.7602 0 0 -0 0.078609</pose>
          <velocity>-3.3e-05 -0.000112 -0.000328 -0.000553 0.000512 -0.000137</velocity>
          <acceleration>0.479641 0.234492 -9.40884 -0.324392 0.492931 -0.143954</acceleration>
          <wrench>23.982 11.7246 -470.442 0 -0 0</wrench>
        </link>
        <link name='gate'>
          <pose frame=''>0.703315 -2.73369 0.933267 -1e-06 1e-06 0.078609</pose>
          <velocity>0.000446 0.000416 0.000386 -0.000565 0.000531 -8.3e-05</velocity>
          <acceleration>0.444277 0.230305 -9.58109 -0.291079 0.512504 -0.451364</acceleration>
          <wrench>0.888553 0.460611 -19.1622 0 -0 0</wrench>
        </link>
      </model>
      <model name='frc2016_portcullis_clone'>
        <pose frame=''>0.579045 2.70232 0.009597 -0.043479 0.000175 0.004032</pose>
        <scale>1 1 1</scale>
        <link name='base'>
          <pose frame=''>0.579045 2.70232 0.009597 -0.043479 0.000175 0.004032</pose>
          <velocity>-0.000731 0.0007 -0.002712 -0.00417 0.004133 0.001611</velocity>
          <acceleration>3.2235 1.51406 -4.21751 2.28184 -0.391664 -2.07251</acceleration>
          <wrench>161.175 75.7029 -210.876 0 -0 0</wrench>
        </link>
        <link name='gate'>
          <pose frame=''>0.550228 2.77159 0.940734 -0.04348 0.000176 0.004035</pose>
          <velocity>0.003065 0.004581 -0.002425 -0.004182 0.003976 0.001026</velocity>
          <acceleration>3.31913 1.43293 -4.33856 1.92118 1.50848 1.60642</acceleration>
          <wrench>6.63826 2.86586 -8.67711 0 -0 0</wrench>
        </link>
      </model>
      <model name='frc2016_sallyport'>
        <pose frame=''>2.07391 -2.73425 1e-06 -9e-06 0 0.009035</pose>
        <scale>1 1 1</scale>
        <link name='base'>
          <pose frame=''>2.07391 -2.73425 1e-06 -9e-06 0 0.009035</pose>
          <velocity>-4e-06 -1e-06 0.004398 0.004733 -9.8e-05 -1.6e-05</velocity>
          <acceleration>0.060608 -7.06969 7.39572 1.11278 0.259579 -0.052276</acceleration>
          <wrench>3.03039 -353.485 369.786 0 -0 0</wrench>
        </link>
        <link name='door'>
          <pose frame=''>2.09618 -3.03788 0.403324 -8e-06 -0 -0.090805</pose>
          <velocity>-0.000158 -0.001457 0.002964 0.004704 -0.000112 0.000278</velocity>
          <acceleration>0.542661 -2.03006 1.29661 0.970643 -1.21238 -2.83359</acceleration>
          <wrench>1.08532 -4.06012 2.59322 0 -0 0</wrench>
        </link>
      </model>
      <model name='frc2016_sallyport_clone'>
        <pose frame=''>-3.39428 2.82487 0 0 -0 0.000807</pose>
        <scale>1 1 1</scale>
        <link name='base'>
          <pose frame=''>-3.39428 2.82487 0 0 -0 0.000807</pose>
          <velocity>0 1.5e-05 0.001278 0.001285 -0.002927 4.1e-05</velocity>
          <acceleration>-2.06622 -0.933761 2.54808 2.79274 0.354138 0.167275</acceleration>
          <wrench>-103.311 -46.6881 127.404 0 -0 0</wrench>
        </link>
        <link name='door'>
          <pose frame=''>-3.37347 2.53269 0.40332 -1e-06 2e-06 -0.079845</pose>
          <velocity>-0.001347 -0.003626 0.00088 0.00107 -0.003358 -0.004854</velocity>
          <acceleration>-2.16053 -0.211945 1.65378 -1.45873 -0.495493 1.89283</acceleration>
          <wrench>-4.32106 -0.423889 3.30755 0 -0 0</wrench>
        </link>
      </model>
      <model name='ground_plane'>
        <pose frame=''>0 0 0 0 -0 0</pose>
        <scale>1 1 1</scale>
        <link name='link'>
          <pose frame=''>0 0 0 0 -0 0</pose>
          <velocity>0 0 0 0 -0 0</velocity>
          <acceleration>0 0 0 0 -0 0</acceleration>
          <wrench>0 0 0 0 -0 0</wrench>
        </link>
      </model>
      <model name='unit_box_0_0'>
        <pose frame=''>-1.51313 0.535035 0.499995 0 -1e-05 -0.040696</pose>
        <scale>1 1 1</scale>
        <link name='link'>
          <pose frame=''>-1.51313 0.535035 0.499995 0 -1e-05 -0.040696</pose>
          <velocity>0 0 0 0 -0 0</velocity>
          <acceleration>-0.010805 -0.00611 -9.78242 0.012325 -0.021601 -4.8e-05</acceleration>
          <wrench>-0.010805 -0.00611 -9.78242 0 -0 0</wrench>
        </link>
      </model>
      <model name='unit_cylinder_0'>
        <pose frame=''>1.51347 -0.411785 0.499991 0 0 -0.213293</pose>
        <scale>1 1 1</scale>
        <link name='link'>
          <pose frame=''>1.51347 -0.411785 0.499991 0 0 -0.213293</pose>
          <velocity>0 0 0 0 -0 0</velocity>
          <acceleration>0 0 -9.8 0 -0 0</acceleration>
          <wrench>0 0 -9.8 0 -0 0</wrench>
        </link>
      </model>
      <light name='sun'>
        <pose frame=''>0 0 10 0 -0 0</pose>
      </light>
      <light name='user_spot_light_0'>
        <pose frame=''>-7.65477 5.52578 5.13694 0 -0.81281 0</pose>
      </light>
      <light name='user_spot_light_1'>
        <pose frame=''>5.41809 -9.93317 6.66074 0.820393 0.286791 0.294574</pose>
      </light>
    </state>
    <gui fullscreen='0'>
      <camera name='user_camera'>
        <pose frame=''>3.6651 -11.3615 5.36282 0 0.369796 1.89219</pose>
        <view_controller>orbit</view_controller>
        <projection_type>perspective</projection_type>
      </camera>
    </gui>
    <model name='unit_cylinder_0'>
      <pose frame=''>1.94742 -0.360933 0.5 0 -0 0</pose>
      <link name='link'>
        <inertial>
          <mass>1</mass>
          <inertia>
            <ixx>0.145833</ixx>
            <ixy>0</ixy>
            <ixz>0</ixz>
            <iyy>0.145833</iyy>
            <iyz>0</iyz>
            <izz>0.125</izz>
          </inertia>
        </inertial>
        <collision name='collision'>
          <geometry>
            <cylinder>
              <radius>0.5</radius>
              <length>1</length>
            </cylinder>
          </geometry>
          <max_contacts>10</max_contacts>
          <surface>
            <contact>
              <ode/>
            </contact>
            <bounce/>
            <friction>
              <torsional>
                <ode/>
              </torsional>
              <ode/>
            </friction>
          </surface>
        </collision>
        <visual name='visual'>
          <geometry>
            <cylinder>
              <radius>0.5</radius>
              <length>1</length>
            </cylinder>
          </geometry>
          <material>
            <script>
              <name>Gazebo/Grey</name>
              <uri>file://media/materials/scripts/gazebo.material</uri>
            </script>
          </material>
        </visual>
        <self_collide>0</self_collide>
        <kinematic>0</kinematic>
        <gravity>1</gravity>
      </link>
    </model>
    <light name='user_spot_light_0' type='spot'>
      <pose frame=''>-3.28458 5.52578 1 0 -0 0</pose>
      <diffuse>0.5 0.5 0.5 1</diffuse>
      <specular>0.1 0.1 0.1 1</specular>
      <direction>0 0 -1</direction>
      <attenuation>
        <range>20</range>
        <constant>0.5</constant>
        <linear>0.01</linear>
        <quadratic>0.001</quadratic>
      </attenuation>
      <cast_shadows>0</cast_shadows>
      <spot>
        <inner_angle>0.6</inner_angle>
        <outer_angle>1</outer_angle>
        <falloff>1</falloff>
      </spot>
    </light>
    <light name='user_spot_light_1' type='spot'>
      <pose frame=''>1.94138 -4.66123 1 0 -0 0</pose>
      <diffuse>0.5 0.5 0.5 1</diffuse>
      <specular>0.1 0.1 0.1 1</specular>
      <direction>0 0 -1</direction>
      <attenuation>
        <range>20</range>
        <constant>0.5</constant>
        <linear>0.01</linear>
        <quadratic>0.001</quadratic>
      </attenuation>
      <cast_shadows>0</cast_shadows>
      <spot>
        <inner_angle>0.6</inner_angle>
        <outer_angle>1</outer_angle>
        <falloff>1</falloff>
      </spot>
    </light>
    <model name='unit_box_0_0'>
      <pose frame=''>0.041319 -2.17716 0.5 0 -0 0</pose>
      <link name='link'>
        <inertial>
          <mass>1</mass>
          <inertia>
            <ixx>0.166667</ixx>
            <ixy>0</ixy>
            <ixz>0</ixz>
            <iyy>0.166667</iyy>
            <iyz>0</iyz>
            <izz>0.166667</izz>
          </inertia>
        </inertial>
        <collision name='collision'>
          <geometry>
            <box>
              <size>1 1 1</size>
            </box>
          </geometry>
          <max_contacts>10</max_contacts>
          <surface>
            <contact>
              <ode/>
            </contact>
            <bounce/>
            <friction>
              <torsional>
                <ode/>
              </torsional>
              <ode/>
            </friction>
          </surface>
        </collision>
        <visual name='visual'>
          <geometry>
            <box>
              <size>1 1 1</size>
            </box>
          </geometry>
          <material>
            <script>
              <name>Gazebo/Grey</name>
              <uri>file://media/materials/scripts/gazebo.material</uri>
            </script>
          </material>
        </visual>
        <self_collide>0</self_collide>
        <kinematic>0</kinematic>
        <gravity>1</gravity>
      </link>
    </model>
    <model name='frc2016_drawbridge'>
      <link name='base'>
        <inertial>
          <mass>10</mass>
          <pose frame=''>0 0 1 0 -0 0</pose>
          <inertia>
            <ixx>3.64907</ixx>
            <ixy>0</ixy>
            <ixz>0</ixz>
            <iyy>4.67075</iyy>
            <iyz>0</iyz>
            <izz>1.66649</izz>
          </inertia>
        </inertial>
        <visual name='platform'>
          <pose frame=''>0 0 0.0425 0 -0 0</pose>
          <geometry>
            <box>
              <size>1.27 0.5969 0.085</size>
            </box>
          </geometry>
        </visual>
        <collision name='platform'>
          <pose frame=''>0 0 0.0425 0 -0 0</pose>
          <geometry>
            <box>
              <size>1.27 0.5969 0.085</size>
            </box>
          </geometry>
          <max_contacts>10</max_contacts>
          <surface>
            <contact>
              <ode/>
            </contact>
            <bounce/>
            <friction>
              <torsional>
                <ode/>
              </torsional>
              <ode/>
            </friction>
          </surface>
        </collision>
        <visual name='right_wall'>
          <pose frame=''>0.55879 0.04444 0.889 0 -0 0</pose>
          <geometry>
            <box>
              <size>0.05715 0.45698 1.77165</size>
            </box>
          </geometry>
        </visual>
        <collision name='right_wall'>
          <pose frame=''>0.55879 0.04444 0.889 0 -0 0</pose>
          <geometry>
            <box>
              <size>0.05715 0.45698 1.77165</size>
            </box>
          </geometry>
          <max_contacts>10</max_contacts>
          <surface>
            <contact>
              <ode/>
            </contact>
            <bounce/>
            <friction>
              <torsional>
                <ode/>
              </torsional>
              <ode/>
            </friction>
          </surface>
        </collision>
        <visual name='left_wall'>
          <pose frame=''>-0.55879 0.04444 0.889 0 -0 0</pose>
          <geometry>
            <box>
              <size>0.05715 0.45698 1.77165</size>
            </box>
          </geometry>
        </visual>
        <collision name='left_wall'>
          <pose frame=''>-0.55879 0.04444 0.889 0 -0 0</pose>
          <geometry>
            <box>
              <size>0.05715 0.45698 1.77165</size>
            </box>
          </geometry>
          <max_contacts>10</max_contacts>
          <surface>
            <contact>
              <ode/>
            </contact>
            <bounce/>
            <friction>
              <torsional>
                <ode/>
              </torsional>
              <ode/>
            </friction>
          </surface>
        </collision>
        <visual name='front_upper_wall'>
          <pose frame=''>0 0.27611 1.84286 0 -0 0</pose>
          <geometry>
            <box>
              <size>1.1557 0.006347 0.254</size>
            </box>
          </geometry>
        </visual>
        <collision name='front_upper_wall'>
          <pose frame=''>0 0.27611 1.84286 0 -0 0</pose>
          <geometry>
            <box>
              <size>1.1557 0.006347 0.254</size>
            </box>
          </geometry>
          <max_contacts>10</max_contacts>
          <surface>
            <contact>
              <ode/>
            </contact>
            <bounce/>
            <friction>
              <torsional>
                <ode/>
              </torsional>
              <ode/>
            </friction>
          </surface>
        </collision>
        <visual name='back_upper_wall'>
          <pose frame=''>0 -0.18722 1.84286 0 -0 0</pose>
          <geometry>
            <box>
              <size>1.1557 0.006347 0.254</size>
            </box>
          </geometry>
        </visual>
        <collision name='back_upper_wall'>
          <pose frame=''>0 -0.18722 1.84286 0 -0 0</pose>
          <geometry>
            <box>
              <size>1.1557 0.006347 0.254</size>
            </box>
          </geometry>
          <max_contacts>10</max_contacts>
          <surface>
            <contact>
              <ode/>
            </contact>
            <bounce/>
            <friction>
              <torsional>
                <ode/>
              </torsional>
              <ode/>
            </friction>
          </surface>
        </collision>
        <self_collide>0</self_collide>
        <kinematic>0</kinematic>
        <gravity>1</gravity>
      </link>
      <link name='bridge'>
        <pose frame=''>0 0.28245 0.50577 0 -0 0</pose>
        <inertial>
          <mass>2</mass>
          <pose frame=''>0 -0.28245 -0.50577 0 -0 0</pose>
          <inertia>
            <ixx>0.139361</ixx>
            <ixy>0</ixy>
            <ixz>0</ixz>
            <iyy>0.357088</iyy>
            <iyz>0</iyz>
            <izz>0.217741</izz>
          </inertia>
        </inertial>
        <visual name='visual'>
          <geometry>
            <box>
              <size>1.14298 0.006347 0.9144</size>
            </box>
          </geometry>
          <material>
            <script>
              <name>Gazebo/WoodFloor</name>
              <uri>__default__</uri>
            </script>
          </material>
        </visual>
        <collision name='collision'>
          <geometry>
            <box>
              <size>1.14298 0.006347 0.9144</size>
            </box>
          </geometry>
          <max_contacts>10</max_contacts>
          <surface>
            <contact>
              <ode/>
            </contact>
            <bounce/>
            <friction>
              <torsional>
                <ode/>
              </torsional>
              <ode/>
            </friction>
          </surface>
        </collision>
        <self_collide>0</self_collide>
        <kinematic>0</kinematic>
        <gravity>1</gravity>
      </link>
      <joint name='bridge_joint' type='revolute'>
        <pose frame=''>0 0 -0.4172 0 -0 0</pose>
        <parent>base</parent>
        <child>bridge</child>
        <axis>
          <xyz>1 0 0</xyz>
          <limit>
            <lower>-2</lower>
            <upper>0</upper>
          </limit>
          <use_parent_model_frame>0</use_parent_model_frame>
          <dynamics>
            <spring_reference>0</spring_reference>
            <spring_stiffness>0</spring_stiffness>
          </dynamics>
        </axis>
      </joint>
      <pose frame=''>-1.94288 -2.67796 0 0 -0 0</pose>
    </model>
    <model name='frc2016_lowbar'>
      <link name='base'>
        <inertial>
          <mass>50</mass>
          <inertia>
            <ixx>0.035543</ixx>
            <ixy>0</ixy>
            <ixz>0</ixz>
            <iyy>0.134412</iyy>
            <iyz>0</iyz>
            <izz>0.165376</izz>
          </inertia>
        </inertial>
        <visual name='platform'>
          <pose frame=''>0 0 0.039065 0 -0 0</pose>
          <geometry>
            <box>
              <size>1.26 0.5996 0.07813</size>
            </box>
          </geometry>
        </visual>
        <collision name='platform'>
          <pose frame=''>0 0 0.039065 0 -0 0</pose>
          <geometry>
            <box>
              <size>1.27 0.6096 0.07813</size>
            </box>
          </geometry>
          <max_contacts>10</max_contacts>
          <surface>
            <contact>
              <ode/>
            </contact>
            <bounce/>
            <friction>
              <torsional>
                <ode/>
              </torsional>
              <ode/>
            </friction>
          </surface>
        </collision>
        <visual name='right_column'>
          <pose frame=''>-0.57845 -0.18464 0.26863 0 -0 0</pose>
          <geometry>
            <cylinder>
              <radius>0.0254</radius>
              <length>0.381</length>
            </cylinder>
          </geometry>
        </visual>
        <collision name='right_column'>
          <pose frame=''>-0.57845 -0.18464 0.26863 0 -0 0</pose>
          <geometry>
            <cylinder>
              <radius>0.0254</radius>
              <length>0.381</length>
            </cylinder>
          </geometry>
          <max_contacts>10</max_contacts>
          <surface>
            <contact>
              <ode/>
            </contact>
            <bounce/>
            <friction>
              <torsional>
                <ode/>
              </torsional>
              <ode/>
            </friction>
          </surface>
        </collision>
        <visual name='left_column'>
          <pose frame=''>0.57845 -0.18464 0.26863 0 -0 0</pose>
          <geometry>
            <cylinder>
              <radius>0.0254</radius>
              <length>0.381</length>
            </cylinder>
          </geometry>
        </visual>
        <collision name='left_column'>
          <pose frame=''>0.57845 -0.18464 0.26863 0 -0 0</pose>
          <geometry>
            <cylinder>
              <radius>0.0254</radius>
              <length>0.381</length>
            </cylinder>
          </geometry>
          <max_contacts>10</max_contacts>
          <surface>
            <contact>
              <ode/>
            </contact>
            <bounce/>
            <friction>
              <torsional>
                <ode/>
              </torsional>
              <ode/>
            </friction>
          </surface>
        </collision>
        <visual name='horizontal'>
          <pose frame=''>0 -0.18464 0.43556 0 1.5707 0</pose>
          <geometry>
            <cylinder>
              <radius>0.0254</radius>
              <length>1.2018</length>
            </cylinder>
          </geometry>
        </visual>
        <collision name='horizontal'>
          <pose frame=''>0 -0.18464 0.43556 0 1.5707 0</pose>
          <geometry>
            <cylinder>
              <radius>0.0254</radius>
              <length>1.2018</length>
            </cylinder>
          </geometry>
          <max_contacts>10</max_contacts>
          <surface>
            <contact>
              <ode/>
            </contact>
            <bounce/>
            <friction>
              <torsional>
                <ode/>
              </torsional>
              <ode/>
            </friction>
          </surface>
        </collision>
        <self_collide>0</self_collide>
        <kinematic>0</kinematic>
        <gravity>1</gravity>
      </link>
      <link name='wall'>
        <pose frame=''>0 -0.1778 0.24323 0 -0 0</pose>
        <inertial>
          <mass>1</mass>
          <inertia>
            <ixx>0.00774528</ixx>
            <ixy>0</ixy>
            <ixz>0</ixz>
            <iyy>0.116613</iyy>
            <iyz>0</iyz>
            <izz>0.108874</izz>
          </inertia>
        </inertial>
        <visual name='visual'>
          <geometry>
            <box>
              <size>1.1176 0.00635 0.3</size>
            </box>
          </geometry>
          <material>
            <ambient>0.46 0.46 0.46 1</ambient>
            <diffuse>0.46 0.46 0.46 1</diffuse>
          </material>
        </visual>
        <collision name='collision'>
          <geometry>
            <box>
              <size>1.143 0.00635 0.3</size>
            </box>
          </geometry>
          <max_contacts>10</max_contacts>
          <surface>
            <contact>
              <ode/>
            </contact>
            <bounce/>
            <friction>
              <torsional>
                <ode/>
              </torsional>
              <ode/>
            </friction>
          </surface>
        </collision>
        <self_collide>0</self_collide>
        <kinematic>0</kinematic>
        <gravity>1</gravity>
      </link>
      <joint name='bar_joint' type='revolute'>
        <pose frame=''>0 0 0.36378 0 -0 0</pose>
        <parent>base</parent>
        <child>wall</child>
        <axis>
          <xyz>1 0 0</xyz>
          <limit>
            <lower>-1.5707</lower>
            <upper>1.5707</upper>
          </limit>
          <use_parent_model_frame>0</use_parent_model_frame>
          <dynamics>
            <spring_reference>0</spring_reference>
            <spring_stiffness>0</spring_stiffness>
          </dynamics>
        </axis>
      </joint>
      <pose frame=''>-0.643553 -2.67539 0 0 -0 0</pose>
    </model>
    <model name='frc2016_portcullis'>
      <link name='base'>
        <inertial>
          <mass>50</mass>
          <pose frame=''>0 0 1.02941 0 -0 0</pose>
          <inertia>
            <ixx>3.81711</ixx>
            <ixy>0</ixy>
            <ixz>0</ixz>
            <iyy>4.87698</iyy>
            <iyz>0</iyz>
            <izz>1.6283</izz>
          </inertia>
        </inertial>
        <visual name='platform'>
          <pose frame=''>0 0 0.07284 0 -0 0</pose>
          <geometry>
            <box>
              <size>1.27 0.5842 0.003175</size>
            </box>
          </geometry>
        </visual>
        <collision name='platform'>
          <pose frame=''>0 0 0.07284 0 -0 0</pose>
          <geometry>
            <box>
              <size>1.27 0.5842 0.003175</size>
            </box>
          </geometry>
          <max_contacts>10</max_contacts>
          <surface>
            <contact>
              <ode/>
            </contact>
            <bounce/>
            <friction>
              <torsional>
                <ode/>
              </torsional>
              <ode/>
            </friction>
          </surface>
        </collision>
        <visual name='left_column'>
          <pose frame=''>0.59284 0 0.99042 0 -0 0</pose>
          <geometry>
            <box>
              <size>0.08375 0.28575 1.83198</size>
            </box>
          </geometry>
        </visual>
        <collision name='left_column'>
          <pose frame=''>0.59284 0 0.99042 0 -0 0</pose>
          <geometry>
            <box>
              <size>0.08375 0.28575 1.83198</size>
            </box>
          </geometry>
          <max_contacts>10</max_contacts>
          <surface>
            <contact>
              <ode/>
            </contact>
            <bounce/>
            <friction>
              <torsional>
                <ode/>
              </torsional>
              <ode/>
            </friction>
          </surface>
        </collision>
        <visual name='right_column'>
          <pose frame=''>-0.57759 0 0.99042 0 -0 0</pose>
          <geometry>
            <box>
              <size>0.08375 0.28575 1.83198</size>
            </box>
          </geometry>
        </visual>
        <collision name='right_column'>
          <pose frame=''>-0.57759 0 0.99042 0 -0 0</pose>
          <geometry>
            <box>
              <size>0.08375 0.28575 1.83198</size>
            </box>
          </geometry>
          <max_contacts>10</max_contacts>
          <surface>
            <contact>
              <ode/>
            </contact>
            <bounce/>
            <friction>
              <torsional>
                <ode/>
              </torsional>
              <ode/>
            </friction>
          </surface>
        </collision>
        <visual name='top'>
          <pose frame=''>-0.00034 0 1.77722 0 -0 0</pose>
          <geometry>
            <box>
              <size>1.22962 0.28575 0.26657</size>
            </box>
          </geometry>
        </visual>
        <collision name='top'>
          <pose frame=''>-0.00034 0 1.77722 0 -0 0</pose>
          <geometry>
            <box>
              <size>1.22962 0.28575 0.26657</size>
            </box>
          </geometry>
          <max_contacts>10</max_contacts>
          <surface>
            <contact>
              <ode/>
            </contact>
            <bounce/>
            <friction>
              <torsional>
                <ode/>
              </torsional>
              <ode/>
            </friction>
          </surface>
        </collision>
        <visual name='castor1'>
          <pose frame=''>-0.45651 -0.16234 0.03272 0 -0 0</pose>
          <geometry>
            <sphere>
              <radius>0.03272</radius>
            </sphere>
          </geometry>
        </visual>
        <collision name='castor1'>
          <pose frame=''>-0.45651 -0.16234 0.03272 0 -0 0</pose>
          <geometry>
            <sphere>
              <radius>0.03272</radius>
            </sphere>
          </geometry>
          <max_contacts>10</max_contacts>
          <surface>
            <contact>
              <ode/>
            </contact>
            <bounce/>
            <friction>
              <torsional>
                <ode/>
              </torsional>
              <ode/>
            </friction>
          </surface>
        </collision>
        <visual name='castor2'>
          <pose frame=''>-0.27883 0.21836 0.03272 0 -0 0</pose>
          <geometry>
            <sphere>
              <radius>0.03272</radius>
            </sphere>
          </geometry>
        </visual>
        <collision name='castor2'>
          <pose frame=''>-0.27883 0.21836 0.03272 0 -0 0</pose>
          <geometry>
            <sphere>
              <radius>0.03272</radius>
            </sphere>
          </geometry>
          <max_contacts>10</max_contacts>
          <surface>
            <contact>
              <ode/>
            </contact>
            <bounce/>
            <friction>
              <torsional>
                <ode/>
              </torsional>
              <ode/>
            </friction>
          </surface>
        </collision>
        <visual name='castor3'>
          <pose frame=''>0.28083 0.21906 0.03272 0 -0 0</pose>
          <geometry>
            <sphere>
              <radius>0.03272</radius>
            </sphere>
          </geometry>
        </visual>
        <collision name='castor3'>
          <pose frame=''>0.28083 0.21906 0.03272 0 -0 0</pose>
          <geometry>
            <sphere>
              <radius>0.03272</radius>
            </sphere>
          </geometry>
          <max_contacts>10</max_contacts>
          <surface>
            <contact>
              <ode/>
            </contact>
            <bounce/>
            <friction>
              <torsional>
                <ode/>
              </torsional>
              <ode/>
            </friction>
          </surface>
        </collision>
        <visual name='castor4'>
          <pose frame=''>0.45871 -0.16186 0.03272 0 -0 0</pose>
          <geometry>
            <sphere>
              <radius>0.03272</radius>
            </sphere>
          </geometry>
        </visual>
        <collision name='castor4'>
          <pose frame=''>0.45871 -0.16186 0.03272 0 -0 0</pose>
          <geometry>
            <sphere>
              <radius>0.03272</radius>
            </sphere>
          </geometry>
          <max_contacts>10</max_contacts>
          <surface>
            <contact>
              <ode/>
            </contact>
            <bounce/>
            <friction>
              <torsional>
                <ode/>
              </torsional>
              <ode/>
            </friction>
          </surface>
        </collision>
        <self_collide>0</self_collide>
        <kinematic>0</kinematic>
        <gravity>1</gravity>
      </link>
      <link name='gate'>
        <pose frame=''>-0.0287 0.02885 0.93327 0 -0 0</pose>
        <inertial>
          <mass>2</mass>
          <pose frame=''>0 0 0 0 -0 0</pose>
          <inertia>
            <ixx>3.81711</ixx>
            <ixy>0</ixy>
            <ixz>0</ixz>
            <iyy>4.87698</iyy>
            <iyz>0</iyz>
            <izz>1.6283</izz>
          </inertia>
        </inertial>
        <collision name='collision'>
          <geometry>
            <box>
              <size>1.1938 0.02496 1.45732</size>
            </box>
          </geometry>
          <max_contacts>10</max_contacts>
          <surface>
            <contact>
              <ode/>
            </contact>
            <bounce/>
            <friction>
              <torsional>
                <ode/>
              </torsional>
              <ode/>
            </friction>
          </surface>
        </collision>
        <visual name='horz_1'>
          <pose frame=''>0 0 -0.70326 0 -0 0</pose>
          <geometry>
            <box>
              <size>1.1938 0.02496 0.0508</size>
            </box>
          </geometry>
          <material>
            <ambient>0.4 0.4 0.4 1</ambient>
            <diffuse>0.4 0.4 0.4 1</diffuse>
          </material>
        </visual>
        <visual name='horz_2'>
          <pose frame=''>0 0 -0.44926 0 -0 0</pose>
          <geometry>
            <box>
              <size>1.1938 0.02496 0.0508</size>
            </box>
          </geometry>
          <material>
            <ambient>0.4 0.4 0.4 1</ambient>
            <diffuse>0.4 0.4 0.4 1</diffuse>
          </material>
        </visual>
        <visual name='horz_3'>
          <pose frame=''>0 0 -0.14517 0 -0 0</pose>
          <geometry>
            <box>
              <size>1.1938 0.02496 0.0508</size>
            </box>
          </geometry>
          <material>
            <ambient>0.4 0.4 0.4 1</ambient>
            <diffuse>0.4 0.4 0.4 1</diffuse>
          </material>
        </visual>
        <visual name='horz_4'>
          <pose frame=''>0 0 0.16034 0 -0 0</pose>
          <geometry>
            <box>
              <size>1.1938 0.02496 0.0508</size>
            </box>
          </geometry>
          <material>
            <ambient>0.4 0.4 0.4 1</ambient>
            <diffuse>0.4 0.4 0.4 1</diffuse>
          </material>
        </visual>
        <visual name='horz_5'>
          <pose frame=''>0 0 0.46514 0 -0 0</pose>
          <geometry>
            <box>
              <size>1.1938 0.02496 0.0508</size>
            </box>
          </geometry>
          <material>
            <ambient>0.4 0.4 0.4 1</ambient>
            <diffuse>0.4 0.4 0.4 1</diffuse>
          </material>
        </visual>
        <visual name='horz_6'>
          <pose frame=''>0 0 0.72994 0 -0 0</pose>
          <geometry>
            <box>
              <size>1.1938 0.02496 0.0508</size>
            </box>
          </geometry>
          <material>
            <ambient>0.4 0.4 0.4 1</ambient>
            <diffuse>0.4 0.4 0.4 1</diffuse>
          </material>
        </visual>
        <visual name='vert_1'>
          <pose frame=''>-0.58448 0 0 0 -0 0</pose>
          <geometry>
            <box>
              <size>0.02495 0.02496 1.45732</size>
            </box>
          </geometry>
          <material>
            <ambient>0.4 0.4 0.4 1</ambient>
            <diffuse>0.4 0.4 0.4 1</diffuse>
          </material>
        </visual>
        <visual name='vert_2'>
          <pose frame=''>-0.38128 0 0 0 -0 0</pose>
          <geometry>
            <box>
              <size>0.0508 0.02496 1.45732</size>
            </box>
          </geometry>
          <material>
            <ambient>0.4 0.4 0.4 1</ambient>
            <diffuse>0.4 0.4 0.4 1</diffuse>
          </material>
        </visual>
        <visual name='vert_3'>
          <pose frame=''>-0.12728 0 0 0 -0 0</pose>
          <geometry>
            <box>
              <size>0.0508 0.02496 1.45732</size>
            </box>
          </geometry>
          <material>
            <ambient>0.4 0.4 0.4 1</ambient>
            <diffuse>0.4 0.4 0.4 1</diffuse>
          </material>
        </visual>
        <visual name='vert_4'>
          <pose frame=''>0.12672 0 0 0 -0 0</pose>
          <geometry>
            <box>
              <size>0.0508 0.02496 1.45732</size>
            </box>
          </geometry>
          <material>
            <ambient>0.4 0.4 0.4 1</ambient>
            <diffuse>0.4 0.4 0.4 1</diffuse>
          </material>
        </visual>
        <visual name='vert_5'>
          <pose frame=''>0.38072 0 0 0 -0 0</pose>
          <geometry>
            <box>
              <size>0.0508 0.02496 1.45732</size>
            </box>
          </geometry>
          <material>
            <ambient>0.4 0.4 0.4 1</ambient>
            <diffuse>0.4 0.4 0.4 1</diffuse>
          </material>
        </visual>
        <visual name='vert_6'>
          <pose frame=''>0.58392 0 0 0 -0 0</pose>
          <geometry>
            <box>
              <size>0.02495 0.02496 1.45732</size>
            </box>
          </geometry>
          <material>
            <ambient>0.4 0.4 0.4 1</ambient>
            <diffuse>0.4 0.4 0.4 1</diffuse>
          </material>
        </visual>
        <self_collide>0</self_collide>
        <kinematic>0</kinematic>
        <gravity>1</gravity>
      </link>
      <joint name='joint' type='prismatic'>
        <parent>base</parent>
        <child>gate</child>
        <axis>
          <xyz>0 0 1</xyz>
          <limit>
            <lower>0</lower>
            <upper>1</upper>
          </limit>
          <use_parent_model_frame>0</use_parent_model_frame>
          <dynamics>
            <spring_reference>0</spring_reference>
            <spring_stiffness>0</spring_stiffness>
          </dynamics>
        </axis>
      </joint>
      <pose frame=''>0.730368 -2.75064 0 0 -0 0</pose>
    </model>
    <model name='frc2016_sallyport'>
      <link name='base'>
        <inertial>
          <mass>50</mass>
          <pose frame=''>0 0 0.35406 0 -0 0</pose>
          <inertia>
            <ixx>0.727808</ixx>
            <ixy>0</ixy>
            <ixz>0</ixz>
            <iyy>1.77488</iyy>
            <iyz>0</iyz>
            <izz>1.64109</izz>
          </inertia>
        </inertial>
        <visual name='platform'>
          <pose frame=''>0 0 0.06974 0 -0 0</pose>
          <geometry>
            <box>
              <size>1.27 0.5969 0.003175</size>
            </box>
          </geometry>
        </visual>
        <collision name='platform'>
          <pose frame=''>0 0 0.06974 0 -0 0</pose>
          <geometry>
            <box>
              <size>1.27 0.5969 0.003175</size>
            </box>
          </geometry>
          <max_contacts>10</max_contacts>
          <surface>
            <contact>
              <ode/>
            </contact>
            <bounce/>
            <friction>
              <torsional>
                <ode/>
              </torsional>
              <ode/>
            </friction>
          </surface>
        </collision>
        <visual name='left_column'>
          <pose frame=''>-0.5588 0.00318 0.38876 0 -0 0</pose>
          <geometry>
            <box>
              <size>0.1524 0.38735 0.635</size>
            </box>
          </geometry>
        </visual>
        <collision name='left_column'>
          <pose frame=''>-0.5588 0.00318 0.38876 0 -0 0</pose>
          <geometry>
            <box>
              <size>0.1524 0.38735 0.635</size>
            </box>
          </geometry>
          <max_contacts>10</max_contacts>
          <surface>
            <contact>
              <ode/>
            </contact>
            <bounce/>
            <friction>
              <torsional>
                <ode/>
              </torsional>
              <ode/>
            </friction>
          </surface>
        </collision>
        <visual name='right_column'>
          <pose frame=''>0.6096 0.00635 0.38876 0 -0 0</pose>
          <geometry>
            <box>
              <size>0.0508 0.381 0.635</size>
            </box>
          </geometry>
        </visual>
        <collision name='right_column'>
          <pose frame=''>0.6096 0.00635 0.38876 0 -0 0</pose>
          <geometry>
            <box>
              <size>0.0508 0.381 0.635</size>
            </box>
          </geometry>
          <max_contacts>10</max_contacts>
          <surface>
            <contact>
              <ode/>
            </contact>
            <bounce/>
            <friction>
              <torsional>
                <ode/>
              </torsional>
              <ode/>
            </friction>
          </surface>
        </collision>
        <visual name='castor1'>
          <pose frame=''>-0.45886 0.15389 0.03487 0 -0 0</pose>
          <geometry>
            <sphere>
              <radius>0.03487</radius>
            </sphere>
          </geometry>
        </visual>
        <collision name='castor1'>
          <pose frame=''>-0.45886 0.15389 0.03487 0 -0 0</pose>
          <geometry>
            <sphere>
              <radius>0.03487</radius>
            </sphere>
          </geometry>
          <max_contacts>10</max_contacts>
          <surface>
            <contact>
              <ode/>
            </contact>
            <bounce/>
            <friction>
              <torsional>
                <ode/>
              </torsional>
              <ode/>
            </friction>
          </surface>
        </collision>
        <visual name='castor2'>
          <pose frame=''>-0.28117 -0.22559 0.03487 0 -0 0</pose>
          <geometry>
            <sphere>
              <radius>0.03487</radius>
            </sphere>
          </geometry>
        </visual>
        <collision name='castor2'>
          <pose frame=''>-0.28117 -0.22559 0.03487 0 -0 0</pose>
          <geometry>
            <sphere>
              <radius>0.03487</radius>
            </sphere>
          </geometry>
          <max_contacts>10</max_contacts>
          <surface>
            <contact>
              <ode/>
            </contact>
            <bounce/>
            <friction>
              <torsional>
                <ode/>
              </torsional>
              <ode/>
            </friction>
          </surface>
        </collision>
        <visual name='castor3'>
          <pose frame=''>0.27933 -0.2272 0.03487 0 -0 0</pose>
          <geometry>
            <sphere>
              <radius>0.03487</radius>
            </sphere>
          </geometry>
        </visual>
        <collision name='castor3'>
          <pose frame=''>0.27933 -0.2272 0.03487 0 -0 0</pose>
          <geometry>
            <sphere>
              <radius>0.03487</radius>
            </sphere>
          </geometry>
          <max_contacts>10</max_contacts>
          <surface>
            <contact>
              <ode/>
            </contact>
            <bounce/>
            <friction>
              <torsional>
                <ode/>
              </torsional>
              <ode/>
            </friction>
          </surface>
        </collision>
        <visual name='castor4'>
          <pose frame=''>0.4571 0.15424 0.03487 0 -0 0</pose>
          <geometry>
            <sphere>
              <radius>0.03487</radius>
            </sphere>
          </geometry>
        </visual>
        <collision name='castor4'>
          <pose frame=''>0.4571 0.15424 0.03487 0 -0 0</pose>
          <geometry>
            <sphere>
              <radius>0.03487</radius>
            </sphere>
          </geometry>
          <max_contacts>10</max_contacts>
          <surface>
            <contact>
              <ode/>
            </contact>
            <bounce/>
            <friction>
              <torsional>
                <ode/>
              </torsional>
              <ode/>
            </friction>
          </surface>
        </collision>
        <self_collide>0</self_collide>
        <kinematic>0</kinematic>
        <gravity>1</gravity>
      </link>
      <link name='door'>
        <pose frame=''>0.02255 -0.24321 0.40332 0 -0 0</pose>
        <inertial>
          <pose frame=''>0 0 0 -1.5707 0 0</pose>
          <mass>2</mass>
          <inertia>
            <ixx>0.0619421</ixx>
            <ixy>0</ixy>
            <ixz>0</ixz>
            <iyy>0.246462</iyy>
            <iyz>0</iyz>
            <izz>0.30839</izz>
          </inertia>
        </inertial>
        <visual name='visual'>
          <geometry>
            <box>
              <size>1.21603 0.00635 0.6096</size>
            </box>
          </geometry>
          <material>
            <script>
              <name>Gazebo/WoodFloor</name>
              <uri>__default__</uri>
            </script>
          </material>
        </visual>
        <collision name='collision'>
          <geometry>
            <box>
              <size>1.21603 0.00635 0.6096</size>
            </box>
          </geometry>
          <max_contacts>10</max_contacts>
          <surface>
            <contact>
              <ode/>
            </contact>
            <bounce/>
            <friction>
              <torsional>
                <ode/>
              </torsional>
              <ode/>
            </friction>
          </surface>
        </collision>
        <self_collide>0</self_collide>
        <kinematic>0</kinematic>
        <gravity>1</gravity>
      </link>
      <joint name='door_joint' type='revolute'>
        <pose frame=''>-0.608015 0 0 0 -0 0</pose>
        <parent>base</parent>
        <child>door</child>
        <axis>
          <xyz>0 0 1</xyz>
          <limit>
            <lower>-3.1415</lower>
            <upper>0</upper>
          </limit>
          <use_parent_model_frame>0</use_parent_model_frame>
          <dynamics>
            <spring_reference>0</spring_reference>
            <spring_stiffness>0</spring_stiffness>
          </dynamics>
        </axis>
      </joint>
      <pose frame=''>2.07395 -2.73562 0 0 -0 0</pose>
    </model>
    <model name='frc2016_chevaldefrise'>
      <link name='base'>
        <inertial>
          <mass>10</mass>
          <pose frame=''>0 0 0.15672 0 -0 0</pose>
          <inertia>
            <ixx>0.380221</ixx>
            <ixy>0</ixy>
            <ixz>0</ixz>
            <iyy>1.43365</iyy>
            <iyz>0</iyz>
            <izz>1.64745</izz>
          </inertia>
        </inertial>
        <visual name='platform'>
          <pose frame=''>0 0 0.06968 0 -0 0</pose>
          <geometry>
            <box>
              <size>1.27 0.5969 0.003175</size>
            </box>
          </geometry>
        </visual>
        <collision name='platform'>
          <pose frame=''>0 0 0.06968 0 -0 0</pose>
          <geometry>
            <box>
              <size>1.27 0.5969 0.003175</size>
            </box>
          </geometry>
          <max_contacts>10</max_contacts>
          <surface>
            <contact>
              <ode/>
            </contact>
            <bounce/>
            <friction>
              <torsional>
                <ode/>
              </torsional>
              <ode/>
            </friction>
          </surface>
        </collision>
        <visual name='bar'>
          <pose frame=''>0 0 0.16855 0 1.5707 0</pose>
          <geometry>
            <cylinder>
              <radius>0.02108</radius>
              <length>1.273</length>
            </cylinder>
          </geometry>
        </visual>
        <collision name='bar'>
          <pose frame=''>0 0 0.16855 0 1.5707 0</pose>
          <geometry>
            <cylinder>
              <radius>0.02108</radius>
              <length>1.27</length>
            </cylinder>
          </geometry>
          <max_contacts>10</max_contacts>
          <surface>
            <contact>
              <ode/>
            </contact>
            <bounce/>
            <friction>
              <torsional>
                <ode/>
              </torsional>
              <ode/>
            </friction>
          </surface>
        </collision>
        <visual name='castor1'>
          <pose frame=''>-0.45653 -0.16581 0.03175 0 -0 0</pose>
          <geometry>
            <sphere>
              <radius>0.03175</radius>
            </sphere>
          </geometry>
        </visual>
        <collision name='castor1'>
          <pose frame=''>-0.45653 -0.16581 0.03175 0 -0 0</pose>
          <geometry>
            <sphere>
              <radius>0.03175</radius>
            </sphere>
          </geometry>
          <max_contacts>10</max_contacts>
          <surface>
            <contact>
              <ode/>
            </contact>
            <bounce/>
            <friction>
              <torsional>
                <ode/>
              </torsional>
              <ode/>
            </friction>
          </surface>
        </collision>
        <visual name='castor2'>
          <pose frame=''>-0.27855 0.21408 0.03175 0 -0 0</pose>
          <geometry>
            <sphere>
              <radius>0.03175</radius>
            </sphere>
          </geometry>
        </visual>
        <collision name='castor2'>
          <pose frame=''>-0.27855 0.21408 0.03175 0 -0 0</pose>
          <geometry>
            <sphere>
              <radius>0.03175</radius>
            </sphere>
          </geometry>
          <max_contacts>10</max_contacts>
          <surface>
            <contact>
              <ode/>
            </contact>
            <bounce/>
            <friction>
              <torsional>
                <ode/>
              </torsional>
              <ode/>
            </friction>
          </surface>
        </collision>
        <visual name='castor3'>
          <pose frame=''>0.28191 0.21419 0.03175 0 -0 0</pose>
          <geometry>
            <sphere>
              <radius>0.03175</radius>
            </sphere>
          </geometry>
        </visual>
        <collision name='castor3'>
          <pose frame=''>0.28191 0.21419 0.03175 0 -0 0</pose>
          <geometry>
            <sphere>
              <radius>0.03175</radius>
            </sphere>
          </geometry>
          <max_contacts>10</max_contacts>
          <surface>
            <contact>
              <ode/>
            </contact>
            <bounce/>
            <friction>
              <torsional>
                <ode/>
              </torsional>
              <ode/>
            </friction>
          </surface>
        </collision>
        <visual name='castor4'>
          <pose frame=''>0.45965 -0.16602 0.03175 0 -0 0</pose>
          <geometry>
            <sphere>
              <radius>0.03175</radius>
            </sphere>
          </geometry>
        </visual>
        <collision name='castor4'>
          <pose frame=''>0.45965 -0.16602 0.03175 0 -0 0</pose>
          <geometry>
            <sphere>
              <radius>0.03175</radius>
            </sphere>
          </geometry>
          <max_contacts>10</max_contacts>
          <surface>
            <contact>
              <ode/>
            </contact>
            <bounce/>
            <friction>
              <torsional>
                <ode/>
              </torsional>
              <ode/>
            </friction>
          </surface>
        </collision>
        <self_collide>0</self_collide>
        <kinematic>0</kinematic>
        <gravity>1</gravity>
      </link>
      <link name='slant1'>
        <pose frame=''>-0.4572 0.01307 0.1997 -0.39732 0 0</pose>
        <inertial>
          <pose frame=''>0 0.1 0 0 -0 0</pose>
          <mass>2</mass>
          <inertia>
            <ixx>0.0606857</ixx>
            <ixy>0</ixy>
            <ixz>0</ixz>
            <iyy>0.0148723</iyy>
            <iyz>0</iyz>
            <izz>0.0755042</izz>
          </inertia>
        </inertial>
        <visual name='visual'>
          <geometry>
            <box>
              <size>0.29845 0.593285 0.0127</size>
            </box>
          </geometry>
          <material>
            <script>
              <name>Gazebo/WoodFloor</name>
              <uri>__default__</uri>
            </script>
          </material>
        </visual>
        <collision name='collision'>
          <geometry>
            <box>
              <size>0.29845 0.593285 0.0127</size>
            </box>
          </geometry>
          <max_contacts>10</max_contacts>
          <surface>
            <contact>
              <ode/>
            </contact>
            <bounce/>
            <friction>
              <torsional>
                <ode/>
              </torsional>
              <ode/>
            </friction>
          </surface>
        </collision>
        <self_collide>0</self_collide>
        <kinematic>0</kinematic>
        <gravity>1</gravity>
      </link>
      <link name='slant2'>
        <pose frame=''>-0.1524 -0.01307 0.1997 0.39732 -0 0</pose>
        <inertial>
          <mass>2</mass>
          <pose frame=''>0 -0.1 0 0 -0 0</pose>
          <inertia>
            <ixx>0.0606857</ixx>
            <ixy>0</ixy>
            <ixz>0</ixz>
            <iyy>0.0148723</iyy>
            <iyz>0</iyz>
            <izz>0.0755042</izz>
          </inertia>
        </inertial>
        <visual name='visual'>
          <geometry>
            <box>
              <size>0.29845 0.593285 0.0127</size>
            </box>
          </geometry>
          <material>
            <script>
              <name>Gazebo/WoodFloor</name>
              <uri>__default__</uri>
            </script>
          </material>
        </visual>
        <collision name='collision'>
          <geometry>
            <box>
              <size>0.29845 0.593285 0.0127</size>
            </box>
          </geometry>
          <max_contacts>10</max_contacts>
          <surface>
            <contact>
              <ode/>
            </contact>
            <bounce/>
            <friction>
              <torsional>
                <ode/>
              </torsional>
              <ode/>
            </friction>
          </surface>
        </collision>
        <self_collide>0</self_collide>
        <kinematic>0</kinematic>
        <gravity>1</gravity>
      </link>
      <link name='slant3'>
        <pose frame=''>0.1524 0.01307 0.1997 -0.39732 0 0</pose>
        <inertial>
          <pose frame=''>0 0.1 0 0 -0 0</pose>
          <mass>2</mass>
          <inertia>
            <ixx>0.0606857</ixx>
            <ixy>0</ixy>
            <ixz>0</ixz>
            <iyy>0.0148723</iyy>
            <iyz>0</iyz>
            <izz>0.0755042</izz>
          </inertia>
        </inertial>
        <visual name='visual'>
          <geometry>
            <box>
              <size>0.29845 0.593285 0.0127</size>
            </box>
          </geometry>
          <material>
            <script>
              <name>Gazebo/WoodFloor</name>
              <uri>__default__</uri>
            </script>
          </material>
        </visual>
        <collision name='collision'>
          <geometry>
            <box>
              <size>0.29845 0.593285 0.0127</size>
            </box>
          </geometry>
          <max_contacts>10</max_contacts>
          <surface>
            <contact>
              <ode/>
            </contact>
            <bounce/>
            <friction>
              <torsional>
                <ode/>
              </torsional>
              <ode/>
            </friction>
          </surface>
        </collision>
        <self_collide>0</self_collide>
        <kinematic>0</kinematic>
        <gravity>1</gravity>
      </link>
      <link name='slant4'>
        <pose frame=''>0.4572 -0.01307 0.1997 0.39732 -0 0</pose>
        <inertial>
          <pose frame=''>0 -0.1 0 0 -0 0</pose>
          <mass>2</mass>
          <inertia>
            <ixx>0.0606857</ixx>
            <ixy>0</ixy>
            <ixz>0</ixz>
            <iyy>0.0148723</iyy>
            <iyz>0</iyz>
            <izz>0.0755042</izz>
          </inertia>
        </inertial>
        <visual name='visual'>
          <geometry>
            <box>
              <size>0.29845 0.593285 0.0127</size>
            </box>
          </geometry>
          <material>
            <script>
              <name>Gazebo/WoodFloor</name>
              <uri>__default__</uri>
            </script>
          </material>
        </visual>
        <collision name='collision'>
          <geometry>
            <box>
              <size>0.29845 0.593285 0.0127</size>
            </box>
          </geometry>
          <max_contacts>10</max_contacts>
          <surface>
            <contact>
              <ode/>
            </contact>
            <bounce/>
            <friction>
              <torsional>
                <ode/>
              </torsional>
              <ode/>
            </friction>
          </surface>
        </collision>
        <self_collide>0</self_collide>
        <kinematic>0</kinematic>
        <gravity>1</gravity>
      </link>
      <joint name='slant1_joint' type='revolute'>
        <parent>base</parent>
        <child>slant1</child>
        <axis>
          <xyz>1 0 0</xyz>
          <limit>
            <lower>0</lower>
            <upper>1.5707</upper>
          </limit>
          <use_parent_model_frame>0</use_parent_model_frame>
          <dynamics>
            <spring_reference>0</spring_reference>
            <spring_stiffness>0</spring_stiffness>
          </dynamics>
        </axis>
      </joint>
      <joint name='slant2_joint' type='revolute'>
        <parent>base</parent>
        <child>slant2</child>
        <axis>
          <xyz>1 0 0</xyz>
          <limit>
            <lower>-1.5707</lower>
            <upper>0</upper>
          </limit>
          <use_parent_model_frame>0</use_parent_model_frame>
          <dynamics>
            <spring_reference>0</spring_reference>
            <spring_stiffness>0</spring_stiffness>
          </dynamics>
        </axis>
      </joint>
      <joint name='slant3_joint' type='revolute'>
        <parent>base</parent>
        <child>slant3</child>
        <axis>
          <xyz>1 0 0</xyz>
          <limit>
            <lower>0</lower>
            <upper>1.5707</upper>
          </limit>
          <use_parent_model_frame>0</use_parent_model_frame>
          <dynamics>
            <spring_reference>0</spring_reference>
            <spring_stiffness>0</spring_stiffness>
          </dynamics>
        </axis>
      </joint>
      <joint name='slant4_joint' type='revolute'>
        <parent>base</parent>
        <child>slant4</child>
        <axis>
          <xyz>1 0 0</xyz>
          <limit>
            <lower>-1.5707</lower>
            <upper>0</upper>
          </limit>
          <use_parent_model_frame>0</use_parent_model_frame>
          <dynamics>
            <spring_reference>0</spring_reference>
            <spring_stiffness>0</spring_stiffness>
          </dynamics>
        </axis>
      </joint>
      <pose frame=''>3.41531 -2.72424 0 0 -0 0</pose>
    </model>
    <model name='frc2016_chevaldefrise_clone'>
      <link name='base'>
        <inertial>
          <mass>10</mass>
          <pose frame=''>0 0 0.15672 0 -0 0</pose>
          <inertia>
            <ixx>0.380221</ixx>
            <ixy>0</ixy>
            <ixz>0</ixz>
            <iyy>1.43365</iyy>
            <iyz>0</iyz>
            <izz>1.64745</izz>
          </inertia>
        </inertial>
        <visual name='platform'>
          <pose frame=''>0 0 0.06968 0 -0 0</pose>
          <geometry>
            <box>
              <size>1.27 0.5969 0.003175</size>
            </box>
          </geometry>
        </visual>
        <collision name='platform'>
          <pose frame=''>0 0 0.06968 0 -0 0</pose>
          <geometry>
            <box>
              <size>1.27 0.5969 0.003175</size>
            </box>
          </geometry>
          <max_contacts>10</max_contacts>
          <surface>
            <contact>
              <ode/>
            </contact>
            <bounce/>
            <friction>
              <torsional>
                <ode/>
              </torsional>
              <ode/>
            </friction>
          </surface>
        </collision>
        <visual name='bar'>
          <pose frame=''>0 0 0.16855 0 1.5707 0</pose>
          <geometry>
            <cylinder>
              <radius>0.02108</radius>
              <length>1.273</length>
            </cylinder>
          </geometry>
        </visual>
        <collision name='bar'>
          <pose frame=''>0 0 0.16855 0 1.5707 0</pose>
          <geometry>
            <cylinder>
              <radius>0.02108</radius>
              <length>1.27</length>
            </cylinder>
          </geometry>
          <max_contacts>10</max_contacts>
          <surface>
            <contact>
              <ode/>
            </contact>
            <bounce/>
            <friction>
              <torsional>
                <ode/>
              </torsional>
              <ode/>
            </friction>
          </surface>
        </collision>
        <visual name='castor1'>
          <pose frame=''>-0.45653 -0.16581 0.03175 0 -0 0</pose>
          <geometry>
            <sphere>
              <radius>0.03175</radius>
            </sphere>
          </geometry>
        </visual>
        <collision name='castor1'>
          <pose frame=''>-0.45653 -0.16581 0.03175 0 -0 0</pose>
          <geometry>
            <sphere>
              <radius>0.03175</radius>
            </sphere>
          </geometry>
          <max_contacts>10</max_contacts>
          <surface>
            <contact>
              <ode/>
            </contact>
            <bounce/>
            <friction>
              <torsional>
                <ode/>
              </torsional>
              <ode/>
            </friction>
          </surface>
        </collision>
        <visual name='castor2'>
          <pose frame=''>-0.27855 0.21408 0.03175 0 -0 0</pose>
          <geometry>
            <sphere>
              <radius>0.03175</radius>
            </sphere>
          </geometry>
        </visual>
        <collision name='castor2'>
          <pose frame=''>-0.27855 0.21408 0.03175 0 -0 0</pose>
          <geometry>
            <sphere>
              <radius>0.03175</radius>
            </sphere>
          </geometry>
          <max_contacts>10</max_contacts>
          <surface>
            <contact>
              <ode/>
            </contact>
            <bounce/>
            <friction>
              <torsional>
                <ode/>
              </torsional>
              <ode/>
            </friction>
          </surface>
        </collision>
        <visual name='castor3'>
          <pose frame=''>0.28191 0.21419 0.03175 0 -0 0</pose>
          <geometry>
            <sphere>
              <radius>0.03175</radius>
            </sphere>
          </geometry>
        </visual>
        <collision name='castor3'>
          <pose frame=''>0.28191 0.21419 0.03175 0 -0 0</pose>
          <geometry>
            <sphere>
              <radius>0.03175</radius>
            </sphere>
          </geometry>
          <max_contacts>10</max_contacts>
          <surface>
            <contact>
              <ode/>
            </contact>
            <bounce/>
            <friction>
              <torsional>
                <ode/>
              </torsional>
              <ode/>
            </friction>
          </surface>
        </collision>
        <visual name='castor4'>
          <pose frame=''>0.45965 -0.16602 0.03175 0 -0 0</pose>
          <geometry>
            <sphere>
              <radius>0.03175</radius>
            </sphere>
          </geometry>
        </visual>
        <collision name='castor4'>
          <pose frame=''>0.45965 -0.16602 0.03175 0 -0 0</pose>
          <geometry>
            <sphere>
              <radius>0.03175</radius>
            </sphere>
          </geometry>
          <max_contacts>10</max_contacts>
          <surface>
            <contact>
              <ode/>
            </contact>
            <bounce/>
            <friction>
              <torsional>
                <ode/>
              </torsional>
              <ode/>
            </friction>
          </surface>
        </collision>
        <self_collide>0</self_collide>
        <kinematic>0</kinematic>
        <gravity>1</gravity>
      </link>
      <link name='slant1'>
        <pose frame=''>-0.4572 0.01307 0.1997 -0.39732 0 0</pose>
        <inertial>
          <pose frame=''>0 0.1 0 0 -0 0</pose>
          <mass>2</mass>
          <inertia>
            <ixx>0.0606857</ixx>
            <ixy>0</ixy>
            <ixz>0</ixz>
            <iyy>0.0148723</iyy>
            <iyz>0</iyz>
            <izz>0.0755042</izz>
          </inertia>
        </inertial>
        <visual name='visual'>
          <geometry>
            <box>
              <size>0.29845 0.593285 0.0127</size>
            </box>
          </geometry>
          <material>
            <script>
              <name>Gazebo/WoodFloor</name>
              <uri>__default__</uri>
            </script>
          </material>
        </visual>
        <collision name='collision'>
          <geometry>
            <box>
              <size>0.29845 0.593285 0.0127</size>
            </box>
          </geometry>
          <max_contacts>10</max_contacts>
          <surface>
            <contact>
              <ode/>
            </contact>
            <bounce/>
            <friction>
              <torsional>
                <ode/>
              </torsional>
              <ode/>
            </friction>
          </surface>
        </collision>
        <self_collide>0</self_collide>
        <kinematic>0</kinematic>
        <gravity>1</gravity>
      </link>
      <link name='slant2'>
        <pose frame=''>-0.1524 -0.01307 0.1997 0.39732 -0 0</pose>
        <inertial>
          <mass>2</mass>
          <pose frame=''>0 -0.1 0 0 -0 0</pose>
          <inertia>
            <ixx>0.0606857</ixx>
            <ixy>0</ixy>
            <ixz>0</ixz>
            <iyy>0.0148723</iyy>
            <iyz>0</iyz>
            <izz>0.0755042</izz>
          </inertia>
        </inertial>
        <visual name='visual'>
          <geometry>
            <box>
              <size>0.29845 0.593285 0.0127</size>
            </box>
          </geometry>
          <material>
            <script>
              <name>Gazebo/WoodFloor</name>
              <uri>__default__</uri>
            </script>
          </material>
        </visual>
        <collision name='collision'>
          <geometry>
            <box>
              <size>0.29845 0.593285 0.0127</size>
            </box>
          </geometry>
          <max_contacts>10</max_contacts>
          <surface>
            <contact>
              <ode/>
            </contact>
            <bounce/>
            <friction>
              <torsional>
                <ode/>
              </torsional>
              <ode/>
            </friction>
          </surface>
        </collision>
        <self_collide>0</self_collide>
        <kinematic>0</kinematic>
        <gravity>1</gravity>
      </link>
      <link name='slant3'>
        <pose frame=''>0.1524 0.01307 0.1997 -0.39732 0 0</pose>
        <inertial>
          <pose frame=''>0 0.1 0 0 -0 0</pose>
          <mass>2</mass>
          <inertia>
            <ixx>0.0606857</ixx>
            <ixy>0</ixy>
            <ixz>0</ixz>
            <iyy>0.0148723</iyy>
            <iyz>0</iyz>
            <izz>0.0755042</izz>
          </inertia>
        </inertial>
        <visual name='visual'>
          <geometry>
            <box>
              <size>0.29845 0.593285 0.0127</size>
            </box>
          </geometry>
          <material>
            <script>
              <name>Gazebo/WoodFloor</name>
              <uri>__default__</uri>
            </script>
          </material>
        </visual>
        <collision name='collision'>
          <geometry>
            <box>
              <size>0.29845 0.593285 0.0127</size>
            </box>
          </geometry>
          <max_contacts>10</max_contacts>
          <surface>
            <contact>
              <ode/>
            </contact>
            <bounce/>
            <friction>
              <torsional>
                <ode/>
              </torsional>
              <ode/>
            </friction>
          </surface>
        </collision>
        <self_collide>0</self_collide>
        <kinematic>0</kinematic>
        <gravity>1</gravity>
      </link>
      <link name='slant4'>
        <pose frame=''>0.4572 -0.01307 0.1997 0.39732 -0 0</pose>
        <inertial>
          <pose frame=''>0 -0.1 0 0 -0 0</pose>
          <mass>2</mass>
          <inertia>
            <ixx>0.0606857</ixx>
            <ixy>0</ixy>
            <ixz>0</ixz>
            <iyy>0.0148723</iyy>
            <iyz>0</iyz>
            <izz>0.0755042</izz>
          </inertia>
        </inertial>
        <visual name='visual'>
          <geometry>
            <box>
              <size>0.29845 0.593285 0.0127</size>
            </box>
          </geometry>
          <material>
            <script>
              <name>Gazebo/WoodFloor</name>
              <uri>__default__</uri>
            </script>
          </material>
        </visual>
        <collision name='collision'>
          <geometry>
            <box>
              <size>0.29845 0.593285 0.0127</size>
            </box>
          </geometry>
          <max_contacts>10</max_contacts>
          <surface>
            <contact>
              <ode/>
            </contact>
            <bounce/>
            <friction>
              <torsional>
                <ode/>
              </torsional>
              <ode/>
            </friction>
          </surface>
        </collision>
        <self_collide>0</self_collide>
        <kinematic>0</kinematic>
        <gravity>1</gravity>
      </link>
      <joint name='slant1_joint' type='revolute'>
        <parent>base</parent>
        <child>slant1</child>
        <axis>
          <xyz>1 0 0</xyz>
          <limit>
            <lower>0</lower>
            <upper>1.5707</upper>
          </limit>
          <use_parent_model_frame>0</use_parent_model_frame>
          <dynamics>
            <spring_reference>0</spring_reference>
            <spring_stiffness>0</spring_stiffness>
          </dynamics>
        </axis>
      </joint>
      <joint name='slant2_joint' type='revolute'>
        <parent>base</parent>
        <child>slant2</child>
        <axis>
          <xyz>1 0 0</xyz>
          <limit>
            <lower>-1.5707</lower>
            <upper>0</upper>
          </limit>
          <use_parent_model_frame>0</use_parent_model_frame>
          <dynamics>
            <spring_reference>0</spring_reference>
            <spring_stiffness>0</spring_stiffness>
          </dynamics>
        </axis>
      </joint>
      <joint name='slant3_joint' type='revolute'>
        <parent>base</parent>
        <child>slant3</child>
        <axis>
          <xyz>1 0 0</xyz>
          <limit>
            <lower>0</lower>
            <upper>1.5707</upper>
          </limit>
          <use_parent_model_frame>0</use_parent_model_frame>
          <dynamics>
            <spring_reference>0</spring_reference>
            <spring_stiffness>0</spring_stiffness>
          </dynamics>
        </axis>
      </joint>
      <joint name='slant4_joint' type='revolute'>
        <parent>base</parent>
        <child>slant4</child>
        <axis>
          <xyz>1 0 0</xyz>
          <limit>
            <lower>-1.5707</lower>
            <upper>0</upper>
          </limit>
          <use_parent_model_frame>0</use_parent_model_frame>
          <dynamics>
            <spring_reference>0</spring_reference>
            <spring_stiffness>0</spring_stiffness>
          </dynamics>
        </axis>
      </joint>
      <pose frame=''>-0.765417 2.79521 -4e-06 2e-06 1.3e-05 2.7e-05</pose>
    </model>
    <model name='frc2016_lowbar_clone'>
      <link name='base'>
        <inertial>
          <mass>50</mass>
          <inertia>
            <ixx>0.035543</ixx>
            <ixy>0</ixy>
            <ixz>0</ixz>
            <iyy>0.134412</iyy>
            <iyz>0</iyz>
            <izz>0.165376</izz>
          </inertia>
        </inertial>
        <visual name='platform'>
          <pose frame=''>0 0 0.039065 0 -0 0</pose>
          <geometry>
            <box>
              <size>1.26 0.5996 0.07813</size>
            </box>
          </geometry>
        </visual>
        <collision name='platform'>
          <pose frame=''>0 0 0.039065 0 -0 0</pose>
          <geometry>
            <box>
              <size>1.27 0.6096 0.07813</size>
            </box>
          </geometry>
          <max_contacts>10</max_contacts>
          <surface>
            <contact>
              <ode/>
            </contact>
            <bounce/>
            <friction>
              <torsional>
                <ode/>
              </torsional>
              <ode/>
            </friction>
          </surface>
        </collision>
        <visual name='right_column'>
          <pose frame=''>-0.57845 -0.18464 0.26863 0 -0 0</pose>
          <geometry>
            <cylinder>
              <radius>0.0254</radius>
              <length>0.381</length>
            </cylinder>
          </geometry>
        </visual>
        <collision name='right_column'>
          <pose frame=''>-0.57845 -0.18464 0.26863 0 -0 0</pose>
          <geometry>
            <cylinder>
              <radius>0.0254</radius>
              <length>0.381</length>
            </cylinder>
          </geometry>
          <max_contacts>10</max_contacts>
          <surface>
            <contact>
              <ode/>
            </contact>
            <bounce/>
            <friction>
              <torsional>
                <ode/>
              </torsional>
              <ode/>
            </friction>
          </surface>
        </collision>
        <visual name='left_column'>
          <pose frame=''>0.57845 -0.18464 0.26863 0 -0 0</pose>
          <geometry>
            <cylinder>
              <radius>0.0254</radius>
              <length>0.381</length>
            </cylinder>
          </geometry>
        </visual>
        <collision name='left_column'>
          <pose frame=''>0.57845 -0.18464 0.26863 0 -0 0</pose>
          <geometry>
            <cylinder>
              <radius>0.0254</radius>
              <length>0.381</length>
            </cylinder>
          </geometry>
          <max_contacts>10</max_contacts>
          <surface>
            <contact>
              <ode/>
            </contact>
            <bounce/>
            <friction>
              <torsional>
                <ode/>
              </torsional>
              <ode/>
            </friction>
          </surface>
        </collision>
        <visual name='horizontal'>
          <pose frame=''>0 -0.18464 0.43556 0 1.5707 0</pose>
          <geometry>
            <cylinder>
              <radius>0.0254</radius>
              <length>1.2018</length>
            </cylinder>
          </geometry>
        </visual>
        <collision name='horizontal'>
          <pose frame=''>0 -0.18464 0.43556 0 1.5707 0</pose>
          <geometry>
            <cylinder>
              <radius>0.0254</radius>
              <length>1.2018</length>
            </cylinder>
          </geometry>
          <max_contacts>10</max_contacts>
          <surface>
            <contact>
              <ode/>
            </contact>
            <bounce/>
            <friction>
              <torsional>
                <ode/>
              </torsional>
              <ode/>
            </friction>
          </surface>
        </collision>
        <self_collide>0</self_collide>
        <kinematic>0</kinematic>
        <gravity>1</gravity>
      </link>
      <link name='wall'>
        <pose frame=''>0 -0.1778 0.24323 0 -0 0</pose>
        <inertial>
          <mass>1</mass>
          <inertia>
            <ixx>0.00774528</ixx>
            <ixy>0</ixy>
            <ixz>0</ixz>
            <iyy>0.116613</iyy>
            <iyz>0</iyz>
            <izz>0.108874</izz>
          </inertia>
        </inertial>
        <visual name='visual'>
          <geometry>
            <box>
              <size>1.1176 0.00635 0.3</size>
            </box>
          </geometry>
          <material>
            <ambient>0.46 0.46 0.46 1</ambient>
            <diffuse>0.46 0.46 0.46 1</diffuse>
          </material>
        </visual>
        <collision name='collision'>
          <geometry>
            <box>
              <size>1.143 0.00635 0.3</size>
            </box>
          </geometry>
          <max_contacts>10</max_contacts>
          <surface>
            <contact>
              <ode/>
            </contact>
            <bounce/>
            <friction>
              <torsional>
                <ode/>
              </torsional>
              <ode/>
            </friction>
          </surface>
        </collision>
        <self_collide>0</self_collide>
        <kinematic>0</kinematic>
        <gravity>1</gravity>
      </link>
      <joint name='bar_joint' type='revolute'>
        <pose frame=''>0 0 0.36378 0 -0 0</pose>
        <parent>base</parent>
        <child>wall</child>
        <axis>
          <xyz>1 0 0</xyz>
          <limit>
            <lower>-1.5707</lower>
            <upper>1.5707</upper>
          </limit>
          <use_parent_model_frame>0</use_parent_model_frame>
          <dynamics>
            <spring_reference>0</spring_reference>
            <spring_stiffness>0</spring_stiffness>
          </dynamics>
        </axis>
      </joint>
      <pose frame=''>-2.12062 2.9004 -1.4e-05 -4.7e-05 -0 0.01344</pose>
    </model>
    <model name='frc2016_portcullis_clone'>
      <link name='base'>
        <inertial>
          <mass>50</mass>
          <pose frame=''>0 0 1.02941 0 -0 0</pose>
          <inertia>
            <ixx>3.81711</ixx>
            <ixy>0</ixy>
            <ixz>0</ixz>
            <iyy>4.87698</iyy>
            <iyz>0</iyz>
            <izz>1.6283</izz>
          </inertia>
        </inertial>
        <visual name='platform'>
          <pose frame=''>0 0 0.07284 0 -0 0</pose>
          <geometry>
            <box>
              <size>1.27 0.5842 0.003175</size>
            </box>
          </geometry>
        </visual>
        <collision name='platform'>
          <pose frame=''>0 0 0.07284 0 -0 0</pose>
          <geometry>
            <box>
              <size>1.27 0.5842 0.003175</size>
            </box>
          </geometry>
          <max_contacts>10</max_contacts>
          <surface>
            <contact>
              <ode/>
            </contact>
            <bounce/>
            <friction>
              <torsional>
                <ode/>
              </torsional>
              <ode/>
            </friction>
          </surface>
        </collision>
        <visual name='left_column'>
          <pose frame=''>0.59284 0 0.99042 0 -0 0</pose>
          <geometry>
            <box>
              <size>0.08375 0.28575 1.83198</size>
            </box>
          </geometry>
        </visual>
        <collision name='left_column'>
          <pose frame=''>0.59284 0 0.99042 0 -0 0</pose>
          <geometry>
            <box>
              <size>0.08375 0.28575 1.83198</size>
            </box>
          </geometry>
          <max_contacts>10</max_contacts>
          <surface>
            <contact>
              <ode/>
            </contact>
            <bounce/>
            <friction>
              <torsional>
                <ode/>
              </torsional>
              <ode/>
            </friction>
          </surface>
        </collision>
        <visual name='right_column'>
          <pose frame=''>-0.57759 0 0.99042 0 -0 0</pose>
          <geometry>
            <box>
              <size>0.08375 0.28575 1.83198</size>
            </box>
          </geometry>
        </visual>
        <collision name='right_column'>
          <pose frame=''>-0.57759 0 0.99042 0 -0 0</pose>
          <geometry>
            <box>
              <size>0.08375 0.28575 1.83198</size>
            </box>
          </geometry>
          <max_contacts>10</max_contacts>
          <surface>
            <contact>
              <ode/>
            </contact>
            <bounce/>
            <friction>
              <torsional>
                <ode/>
              </torsional>
              <ode/>
            </friction>
          </surface>
        </collision>
        <visual name='top'>
          <pose frame=''>-0.00034 0 1.77722 0 -0 0</pose>
          <geometry>
            <box>
              <size>1.22962 0.28575 0.26657</size>
            </box>
          </geometry>
        </visual>
        <collision name='top'>
          <pose frame=''>-0.00034 0 1.77722 0 -0 0</pose>
          <geometry>
            <box>
              <size>1.22962 0.28575 0.26657</size>
            </box>
          </geometry>
          <max_contacts>10</max_contacts>
          <surface>
            <contact>
              <ode/>
            </contact>
            <bounce/>
            <friction>
              <torsional>
                <ode/>
              </torsional>
              <ode/>
            </friction>
          </surface>
        </collision>
        <visual name='castor1'>
          <pose frame=''>-0.45651 -0.16234 0.03272 0 -0 0</pose>
          <geometry>
            <sphere>
              <radius>0.03272</radius>
            </sphere>
          </geometry>
        </visual>
        <collision name='castor1'>
          <pose frame=''>-0.45651 -0.16234 0.03272 0 -0 0</pose>
          <geometry>
            <sphere>
              <radius>0.03272</radius>
            </sphere>
          </geometry>
          <max_contacts>10</max_contacts>
          <surface>
            <contact>
              <ode/>
            </contact>
            <bounce/>
            <friction>
              <torsional>
                <ode/>
              </torsional>
              <ode/>
            </friction>
          </surface>
        </collision>
        <visual name='castor2'>
          <pose frame=''>-0.27883 0.21836 0.03272 0 -0 0</pose>
          <geometry>
            <sphere>
              <radius>0.03272</radius>
            </sphere>
          </geometry>
        </visual>
        <collision name='castor2'>
          <pose frame=''>-0.27883 0.21836 0.03272 0 -0 0</pose>
          <geometry>
            <sphere>
              <radius>0.03272</radius>
            </sphere>
          </geometry>
          <max_contacts>10</max_contacts>
          <surface>
            <contact>
              <ode/>
            </contact>
            <bounce/>
            <friction>
              <torsional>
                <ode/>
              </torsional>
              <ode/>
            </friction>
          </surface>
        </collision>
        <visual name='castor3'>
          <pose frame=''>0.28083 0.21906 0.03272 0 -0 0</pose>
          <geometry>
            <sphere>
              <radius>0.03272</radius>
            </sphere>
          </geometry>
        </visual>
        <collision name='castor3'>
          <pose frame=''>0.28083 0.21906 0.03272 0 -0 0</pose>
          <geometry>
            <sphere>
              <radius>0.03272</radius>
            </sphere>
          </geometry>
          <max_contacts>10</max_contacts>
          <surface>
            <contact>
              <ode/>
            </contact>
            <bounce/>
            <friction>
              <torsional>
                <ode/>
              </torsional>
              <ode/>
            </friction>
          </surface>
        </collision>
        <visual name='castor4'>
          <pose frame=''>0.45871 -0.16186 0.03272 0 -0 0</pose>
          <geometry>
            <sphere>
              <radius>0.03272</radius>
            </sphere>
          </geometry>
        </visual>
        <collision name='castor4'>
          <pose frame=''>0.45871 -0.16186 0.03272 0 -0 0</pose>
          <geometry>
            <sphere>
              <radius>0.03272</radius>
            </sphere>
          </geometry>
          <max_contacts>10</max_contacts>
          <surface>
            <contact>
              <ode/>
            </contact>
            <bounce/>
            <friction>
              <torsional>
                <ode/>
              </torsional>
              <ode/>
            </friction>
          </surface>
        </collision>
        <self_collide>0</self_collide>
        <kinematic>0</kinematic>
        <gravity>1</gravity>
      </link>
      <link name='gate'>
        <pose frame=''>-0.0287 0.02885 0.93327 0 -0 0</pose>
        <inertial>
          <mass>2</mass>
          <pose frame=''>0 0 0 0 -0 0</pose>
          <inertia>
            <ixx>3.81711</ixx>
            <ixy>0</ixy>
            <ixz>0</ixz>
            <iyy>4.87698</iyy>
            <iyz>0</iyz>
            <izz>1.6283</izz>
          </inertia>
        </inertial>
        <collision name='collision'>
          <geometry>
            <box>
              <size>1.1938 0.02496 1.45732</size>
            </box>
          </geometry>
          <max_contacts>10</max_contacts>
          <surface>
            <contact>
              <ode/>
            </contact>
            <bounce/>
            <friction>
              <torsional>
                <ode/>
              </torsional>
              <ode/>
            </friction>
          </surface>
        </collision>
        <visual name='horz_1'>
          <pose frame=''>0 0 -0.70326 0 -0 0</pose>
          <geometry>
            <box>
              <size>1.1938 0.02496 0.0508</size>
            </box>
          </geometry>
          <material>
            <ambient>0.4 0.4 0.4 1</ambient>
            <diffuse>0.4 0.4 0.4 1</diffuse>
          </material>
        </visual>
        <visual name='horz_2'>
          <pose frame=''>0 0 -0.44926 0 -0 0</pose>
          <geometry>
            <box>
              <size>1.1938 0.02496 0.0508</size>
            </box>
          </geometry>
          <material>
            <ambient>0.4 0.4 0.4 1</ambient>
            <diffuse>0.4 0.4 0.4 1</diffuse>
          </material>
        </visual>
        <visual name='horz_3'>
          <pose frame=''>0 0 -0.14517 0 -0 0</pose>
          <geometry>
            <box>
              <size>1.1938 0.02496 0.0508</size>
            </box>
          </geometry>
          <material>
            <ambient>0.4 0.4 0.4 1</ambient>
            <diffuse>0.4 0.4 0.4 1</diffuse>
          </material>
        </visual>
        <visual name='horz_4'>
          <pose frame=''>0 0 0.16034 0 -0 0</pose>
          <geometry>
            <box>
              <size>1.1938 0.02496 0.0508</size>
            </box>
          </geometry>
          <material>
            <ambient>0.4 0.4 0.4 1</ambient>
            <diffuse>0.4 0.4 0.4 1</diffuse>
          </material>
        </visual>
        <visual name='horz_5'>
          <pose frame=''>0 0 0.46514 0 -0 0</pose>
          <geometry>
            <box>
              <size>1.1938 0.02496 0.0508</size>
            </box>
          </geometry>
          <material>
            <ambient>0.4 0.4 0.4 1</ambient>
            <diffuse>0.4 0.4 0.4 1</diffuse>
          </material>
        </visual>
        <visual name='horz_6'>
          <pose frame=''>0 0 0.72994 0 -0 0</pose>
          <geometry>
            <box>
              <size>1.1938 0.02496 0.0508</size>
            </box>
          </geometry>
          <material>
            <ambient>0.4 0.4 0.4 1</ambient>
            <diffuse>0.4 0.4 0.4 1</diffuse>
          </material>
        </visual>
        <visual name='vert_1'>
          <pose frame=''>-0.58448 0 0 0 -0 0</pose>
          <geometry>
            <box>
              <size>0.02495 0.02496 1.45732</size>
            </box>
          </geometry>
          <material>
            <ambient>0.4 0.4 0.4 1</ambient>
            <diffuse>0.4 0.4 0.4 1</diffuse>
          </material>
        </visual>
        <visual name='vert_2'>
          <pose frame=''>-0.38128 0 0 0 -0 0</pose>
          <geometry>
            <box>
              <size>0.0508 0.02496 1.45732</size>
            </box>
          </geometry>
          <material>
            <ambient>0.4 0.4 0.4 1</ambient>
            <diffuse>0.4 0.4 0.4 1</diffuse>
          </material>
        </visual>
        <visual name='vert_3'>
          <pose frame=''>-0.12728 0 0 0 -0 0</pose>
          <geometry>
            <box>
              <size>0.0508 0.02496 1.45732</size>
            </box>
          </geometry>
          <material>
            <ambient>0.4 0.4 0.4 1</ambient>
            <diffuse>0.4 0.4 0.4 1</diffuse>
          </material>
        </visual>
        <visual name='vert_4'>
          <pose frame=''>0.12672 0 0 0 -0 0</pose>
          <geometry>
            <box>
              <size>0.0508 0.02496 1.45732</size>
            </box>
          </geometry>
          <material>
            <ambient>0.4 0.4 0.4 1</ambient>
            <diffuse>0.4 0.4 0.4 1</diffuse>
          </material>
        </visual>
        <visual name='vert_5'>
          <pose frame=''>0.38072 0 0 0 -0 0</pose>
          <geometry>
            <box>
              <size>0.0508 0.02496 1.45732</size>
            </box>
          </geometry>
          <material>
            <ambient>0.4 0.4 0.4 1</ambient>
            <diffuse>0.4 0.4 0.4 1</diffuse>
          </material>
        </visual>
        <visual name='vert_6'>
          <pose frame=''>0.58392 0 0 0 -0 0</pose>
          <geometry>
            <box>
              <size>0.02495 0.02496 1.45732</size>
            </box>
          </geometry>
          <material>
            <ambient>0.4 0.4 0.4 1</ambient>
            <diffuse>0.4 0.4 0.4 1</diffuse>
          </material>
        </visual>
        <self_collide>0</self_collide>
        <kinematic>0</kinematic>
        <gravity>1</gravity>
      </link>
      <joint name='joint' type='prismatic'>
        <parent>base</parent>
        <child>gate</child>
        <axis>
          <xyz>0 0 1</xyz>
          <limit>
            <lower>0</lower>
            <upper>1</upper>
          </limit>
          <use_parent_model_frame>0</use_parent_model_frame>
          <dynamics>
            <spring_reference>0</spring_reference>
            <spring_stiffness>0</spring_stiffness>
          </dynamics>
        </axis>
      </joint>
      <pose frame=''>0.543375 2.74139 -0 1e-06 1e-06 0.071993</pose>
    </model>
    <model name='frc2016_sallyport_clone'>
      <link name='base'>
        <inertial>
          <mass>50</mass>
          <pose frame=''>0 0 0.35406 0 -0 0</pose>
          <inertia>
            <ixx>0.727808</ixx>
            <ixy>0</ixy>
            <ixz>0</ixz>
            <iyy>1.77488</iyy>
            <iyz>0</iyz>
            <izz>1.64109</izz>
          </inertia>
        </inertial>
        <visual name='platform'>
          <pose frame=''>0 0 0.06974 0 -0 0</pose>
          <geometry>
            <box>
              <size>1.27 0.5969 0.003175</size>
            </box>
          </geometry>
        </visual>
        <collision name='platform'>
          <pose frame=''>0 0 0.06974 0 -0 0</pose>
          <geometry>
            <box>
              <size>1.27 0.5969 0.003175</size>
            </box>
          </geometry>
          <max_contacts>10</max_contacts>
          <surface>
            <contact>
              <ode/>
            </contact>
            <bounce/>
            <friction>
              <torsional>
                <ode/>
              </torsional>
              <ode/>
            </friction>
          </surface>
        </collision>
        <visual name='left_column'>
          <pose frame=''>-0.5588 0.00318 0.38876 0 -0 0</pose>
          <geometry>
            <box>
              <size>0.1524 0.38735 0.635</size>
            </box>
          </geometry>
        </visual>
        <collision name='left_column'>
          <pose frame=''>-0.5588 0.00318 0.38876 0 -0 0</pose>
          <geometry>
            <box>
              <size>0.1524 0.38735 0.635</size>
            </box>
          </geometry>
          <max_contacts>10</max_contacts>
          <surface>
            <contact>
              <ode/>
            </contact>
            <bounce/>
            <friction>
              <torsional>
                <ode/>
              </torsional>
              <ode/>
            </friction>
          </surface>
        </collision>
        <visual name='right_column'>
          <pose frame=''>0.6096 0.00635 0.38876 0 -0 0</pose>
          <geometry>
            <box>
              <size>0.0508 0.381 0.635</size>
            </box>
          </geometry>
        </visual>
        <collision name='right_column'>
          <pose frame=''>0.6096 0.00635 0.38876 0 -0 0</pose>
          <geometry>
            <box>
              <size>0.0508 0.381 0.635</size>
            </box>
          </geometry>
          <max_contacts>10</max_contacts>
          <surface>
            <contact>
              <ode/>
            </contact>
            <bounce/>
            <friction>
              <torsional>
                <ode/>
              </torsional>
              <ode/>
            </friction>
          </surface>
        </collision>
        <visual name='castor1'>
          <pose frame=''>-0.45886 0.15389 0.03487 0 -0 0</pose>
          <geometry>
            <sphere>
              <radius>0.03487</radius>
            </sphere>
          </geometry>
        </visual>
        <collision name='castor1'>
          <pose frame=''>-0.45886 0.15389 0.03487 0 -0 0</pose>
          <geometry>
            <sphere>
              <radius>0.03487</radius>
            </sphere>
          </geometry>
          <max_contacts>10</max_contacts>
          <surface>
            <contact>
              <ode/>
            </contact>
            <bounce/>
            <friction>
              <torsional>
                <ode/>
              </torsional>
              <ode/>
            </friction>
          </surface>
        </collision>
        <visual name='castor2'>
          <pose frame=''>-0.28117 -0.22559 0.03487 0 -0 0</pose>
          <geometry>
            <sphere>
              <radius>0.03487</radius>
            </sphere>
          </geometry>
        </visual>
        <collision name='castor2'>
          <pose frame=''>-0.28117 -0.22559 0.03487 0 -0 0</pose>
          <geometry>
            <sphere>
              <radius>0.03487</radius>
            </sphere>
          </geometry>
          <max_contacts>10</max_contacts>
          <surface>
            <contact>
              <ode/>
            </contact>
            <bounce/>
            <friction>
              <torsional>
                <ode/>
              </torsional>
              <ode/>
            </friction>
          </surface>
        </collision>
        <visual name='castor3'>
          <pose frame=''>0.27933 -0.2272 0.03487 0 -0 0</pose>
          <geometry>
            <sphere>
              <radius>0.03487</radius>
            </sphere>
          </geometry>
        </visual>
        <collision name='castor3'>
          <pose frame=''>0.27933 -0.2272 0.03487 0 -0 0</pose>
          <geometry>
            <sphere>
              <radius>0.03487</radius>
            </sphere>
          </geometry>
          <max_contacts>10</max_contacts>
          <surface>
            <contact>
              <ode/>
            </contact>
            <bounce/>
            <friction>
              <torsional>
                <ode/>
              </torsional>
              <ode/>
            </friction>
          </surface>
        </collision>
        <visual name='castor4'>
          <pose frame=''>0.4571 0.15424 0.03487 0 -0 0</pose>
          <geometry>
            <sphere>
              <radius>0.03487</radius>
            </sphere>
          </geometry>
        </visual>
        <collision name='castor4'>
          <pose frame=''>0.4571 0.15424 0.03487 0 -0 0</pose>
          <geometry>
            <sphere>
              <radius>0.03487</radius>
            </sphere>
          </geometry>
          <max_contacts>10</max_contacts>
          <surface>
            <contact>
              <ode/>
            </contact>
            <bounce/>
            <friction>
              <torsional>
                <ode/>
              </torsional>
              <ode/>
            </friction>
          </surface>
        </collision>
        <self_collide>0</self_collide>
        <kinematic>0</kinematic>
        <gravity>1</gravity>
      </link>
      <link name='door'>
        <pose frame=''>0.02255 -0.24321 0.40332 0 -0 0</pose>
        <inertial>
          <pose frame=''>0 0 0 -1.5707 0 0</pose>
          <mass>2</mass>
          <inertia>
            <ixx>0.0619421</ixx>
            <ixy>0</ixy>
            <ixz>0</ixz>
            <iyy>0.246462</iyy>
            <iyz>0</iyz>
            <izz>0.30839</izz>
          </inertia>
        </inertial>
        <visual name='visual'>
          <geometry>
            <box>
              <size>1.21603 0.00635 0.6096</size>
            </box>
          </geometry>
          <material>
            <script>
              <name>Gazebo/WoodFloor</name>
              <uri>__default__</uri>
            </script>
          </material>
        </visual>
        <collision name='collision'>
          <geometry>
            <box>
              <size>1.21603 0.00635 0.6096</size>
            </box>
          </geometry>
          <max_contacts>10</max_contacts>
          <surface>
            <contact>
              <ode/>
            </contact>
            <bounce/>
            <friction>
              <torsional>
                <ode/>
              </torsional>
              <ode/>
            </friction>
          </surface>
        </collision>
        <self_collide>0</self_collide>
        <kinematic>0</kinematic>
        <gravity>1</gravity>
      </link>
      <joint name='door_joint' type='revolute'>
        <pose frame=''>-0.608015 0 0 0 -0 0</pose>
        <parent>base</parent>
        <child>door</child>
        <axis>
          <xyz>0 0 1</xyz>
          <limit>
            <lower>-3.1415</lower>
            <upper>0</upper>
          </limit>
          <use_parent_model_frame>0</use_parent_model_frame>
          <dynamics>
            <spring_reference>0</spring_reference>
            <spring_stiffness>0</spring_stiffness>
          </dynamics>
        </axis>
      </joint>
      <pose frame=''>-3.37842 2.82173 0 2e-06 -0 0.00573</pose>
    </model>
    <model name='frc2016_drawbridge_clone'>
      <link name='base'>
        <inertial>
          <mass>10</mass>
          <pose frame=''>0 0 1 0 -0 0</pose>
          <inertia>
            <ixx>3.64907</ixx>
            <ixy>0</ixy>
            <ixz>0</ixz>
            <iyy>4.67075</iyy>
            <iyz>0</iyz>
            <izz>1.66649</izz>
          </inertia>
        </inertial>
        <visual name='platform'>
          <pose frame=''>0 0 0.0425 0 -0 0</pose>
          <geometry>
            <box>
              <size>1.27 0.5969 0.085</size>
            </box>
          </geometry>
        </visual>
        <collision name='platform'>
          <pose frame=''>0 0 0.0425 0 -0 0</pose>
          <geometry>
            <box>
              <size>1.27 0.5969 0.085</size>
            </box>
          </geometry>
          <max_contacts>10</max_contacts>
          <surface>
            <contact>
              <ode/>
            </contact>
            <bounce/>
            <friction>
              <torsional>
                <ode/>
              </torsional>
              <ode/>
            </friction>
          </surface>
        </collision>
        <visual name='right_wall'>
          <pose frame=''>0.55879 0.04444 0.889 0 -0 0</pose>
          <geometry>
            <box>
              <size>0.05715 0.45698 1.77165</size>
            </box>
          </geometry>
        </visual>
        <collision name='right_wall'>
          <pose frame=''>0.55879 0.04444 0.889 0 -0 0</pose>
          <geometry>
            <box>
              <size>0.05715 0.45698 1.77165</size>
            </box>
          </geometry>
          <max_contacts>10</max_contacts>
          <surface>
            <contact>
              <ode/>
            </contact>
            <bounce/>
            <friction>
              <torsional>
                <ode/>
              </torsional>
              <ode/>
            </friction>
          </surface>
        </collision>
        <visual name='left_wall'>
          <pose frame=''>-0.55879 0.04444 0.889 0 -0 0</pose>
          <geometry>
            <box>
              <size>0.05715 0.45698 1.77165</size>
            </box>
          </geometry>
        </visual>
        <collision name='left_wall'>
          <pose frame=''>-0.55879 0.04444 0.889 0 -0 0</pose>
          <geometry>
            <box>
              <size>0.05715 0.45698 1.77165</size>
            </box>
          </geometry>
          <max_contacts>10</max_contacts>
          <surface>
            <contact>
              <ode/>
            </contact>
            <bounce/>
            <friction>
              <torsional>
                <ode/>
              </torsional>
              <ode/>
            </friction>
          </surface>
        </collision>
        <visual name='front_upper_wall'>
          <pose frame=''>0 0.27611 1.84286 0 -0 0</pose>
          <geometry>
            <box>
              <size>1.1557 0.006347 0.254</size>
            </box>
          </geometry>
        </visual>
        <collision name='front_upper_wall'>
          <pose frame=''>0 0.27611 1.84286 0 -0 0</pose>
          <geometry>
            <box>
              <size>1.1557 0.006347 0.254</size>
            </box>
          </geometry>
          <max_contacts>10</max_contacts>
          <surface>
            <contact>
              <ode/>
            </contact>
            <bounce/>
            <friction>
              <torsional>
                <ode/>
              </torsional>
              <ode/>
            </friction>
          </surface>
        </collision>
        <visual name='back_upper_wall'>
          <pose frame=''>0 -0.18722 1.84286 0 -0 0</pose>
          <geometry>
            <box>
              <size>1.1557 0.006347 0.254</size>
            </box>
          </geometry>
        </visual>
        <collision name='back_upper_wall'>
          <pose frame=''>0 -0.18722 1.84286 0 -0 0</pose>
          <geometry>
            <box>
              <size>1.1557 0.006347 0.254</size>
            </box>
          </geometry>
          <max_contacts>10</max_contacts>
          <surface>
            <contact>
              <ode/>
            </contact>
            <bounce/>
            <friction>
              <torsional>
                <ode/>
              </torsional>
              <ode/>
            </friction>
          </surface>
        </collision>
        <self_collide>0</self_collide>
        <kinematic>0</kinematic>
        <gravity>1</gravity>
      </link>
      <link name='bridge'>
        <pose frame=''>0 0.28245 0.50577 0 -0 0</pose>
        <inertial>
          <mass>2</mass>
          <pose frame=''>0 -0.28245 -0.50577 0 -0 0</pose>
          <inertia>
            <ixx>0.139361</ixx>
            <ixy>0</ixy>
            <ixz>0</ixz>
            <iyy>0.357088</iyy>
            <iyz>0</iyz>
            <izz>0.217741</izz>
          </inertia>
        </inertial>
        <visual name='visual'>
          <geometry>
            <box>
              <size>1.14298 0.006347 0.9144</size>
            </box>
          </geometry>
          <material>
            <script>
              <name>Gazebo/WoodFloor</name>
              <uri>__default__</uri>
            </script>
          </material>
        </visual>
        <collision name='collision'>
          <geometry>
            <box>
              <size>1.14298 0.006347 0.9144</size>
            </box>
          </geometry>
          <max_contacts>10</max_contacts>
          <surface>
            <contact>
              <ode/>
            </contact>
            <bounce/>
            <friction>
              <torsional>
                <ode/>
              </torsional>
              <ode/>
            </friction>
          </surface>
        </collision>
        <self_collide>0</self_collide>
        <kinematic>0</kinematic>
        <gravity>1</gravity>
      </link>
      <joint name='bridge_joint' type='revolute'>
        <pose frame=''>0 0 -0.4172 0 -0 0</pose>
        <parent>base</parent>
        <child>bridge</child>
        <axis>
          <xyz>1 0 0</xyz>
          <limit>
            <lower>-2</lower>
            <upper>0</upper>
          </limit>
          <use_parent_model_frame>0</use_parent_model_frame>
          <dynamics>
            <spring_reference>0</spring_reference>
            <spring_stiffness>0</spring_stiffness>
          </dynamics>
        </axis>
      </joint>
      <pose frame=''>1.96163 2.86591 -0 2e-06 -0 0.00215</pose>
    </model>
  </world>
</sdf>
